Workbook

Sheet ダッシュボード
A1: 介護校 マーケティング 週次分析ダッシュボード
A2: 実測ベース立て直し版 ／ 数値の出どこ：スプレッドシート管理（手入力） ／ 毎週「週次データ」タブに貼って更新
A4: ① 目標設定（ここを編集／黄色セルが前提）
A5: 契約単価（FC取り分・円） | B5: 800000 | C5: ← 1契約あたりの介護校売上
A6: 許容CPA上限（円） | B6: 307000 | C6: ← 1成約あたり広告費の上限ライン
A7: 目標CPL（円） | B7: 3000
A8: 目標 商談化率 | B8: 0.08 | C8: ← 第1段の目標（現状4%の2倍）
A9: 目標 成約率 | B9: 0.2 | C9: ← 第1段の目標（現状12%→）
A10: 目標 月予算（円） | B10: 1050000 | C10: ← 現状75万から微増で運用
A12: ② 現状（実測） vs 目標（第1段）
A13: 指標 | B13: 現状（実測・月換算） | C13: 目標（第1段） | D13: 判定
A14: 広告費 / 月（円） | B14: 755563 | C14: =$B$10 -> 1050000
A15: CV（リード）/ 月（件） | B15: 276 | C15: =$B$10/$B$7 -> 350
A16: 歩留まり（商談化率） | B16: 0.04 | C16: =$B$8 -> 0.08 | D16: =IF(B16>=C16,"◎ 達成",IF(B16>=C16*0.75,"△ あと一歩","✗ 未達")) -> ✗ 未達
A17: 商談 / 月（件） | B17: =B15*B16 -> 11.04 | C17: =C15*C16 -> 28
A18: 成約率 | B18: 0.12 | C18: =$B$9 -> 0.2 | D18: =IF(B18>=C18,"◎ 達成",IF(B18>=C18*0.75,"△ あと一歩","✗ 未達")) -> ✗ 未達
A19: 成約 / 月（件） | B19: =B17*B18 -> 1.3248 | C19: =C17*C18 -> 5.6 | D19: =IF(B19>=C19,"◎ 達成",IF(B19>=C19*0.75,"△ あと一歩","✗ 未達")) -> ✗ 未達
A20: CPL（円） | B20: =B14/B15 -> 2737.5471 | C20: =$B$7 -> 3000
A21: 1成約あたり広告費（円） | B21: =IFERROR(B14/B19,0) -> 570322.31 | C21: =IFERROR(C14/C19,0) -> 187500 | D21: =IF(B21<=C21,"◎ 達成",IF(B21<=C21*1.3,"△ あと一歩","✗ 未達")) -> ✗ 未達
A22: FC売上 / 月（円） | B22: =B19*$B$5 -> 1059840 | C22: =C19*$B$5 -> 4480000
A23: 年FC売上（円） | B23: =B22*12 -> 12718080 | C23: =C22*12 -> 53760000 | D23: =IF(B23>=C23,"◎ 達成",IF(B23>=C23*0.75,"△ あと一歩","✗ 未達")) -> ✗ 未達
A25: ※「現状」列の青字（広告費・リード・商談化率・成約率）は実測値。ここを毎月の実数に更新すると全体が再計算されます。判定は ◎達成／△あと一歩(目標の75%以上)／✗未達。1成約あたり広告費は許容CPA基準で判定。

Sheet 日次入力
A1: 日次入力（毎日1行ずつ入力）
A2: 日付・媒体・キャンペーンを選び、その日の数字を入力。媒体別CPのW10以降に自動集計。商談・成約は実施日で記録。
A3: 日付 | B3: 媒体 | C3: キャンペーン | D3: 消費金額 | E3: IMP | F3: クリック | G3: CV | H3: 商談 | I3: 成約
A4: 46182 | B4: Meta | C4: Metaウェビナー | D4: 16749 | E4: 5791 | F4: 90 | G4: 18 | H4: 0 | I4: 0
A5: 46182 | B5: Meta | C5: Meta介護校 | D5: 19628 | E5: 2821 | F5: 92 | G5: 3 | H5: 0 | I5: 0
A6: 46182 | B6: Meta | C6: MetaClaude | D6: 6308 | E6: 1734 | F6: 55 | G6: 8 | H6: 0 | I6: 0
A7: 46183 | B7: Meta | C7: Metaウェビナー | D7: 15510 | E7: 5433 | F7: 109 | G7: 10 | H7: 0 | I7: 0
A8: 46183 | B8: Meta | C8: Meta介護校 | D8: 19628 | E8: 2821 | F8: 92 | G8: 3 | H8: 0 | I8: 0
A9: 46183 | B9: Meta | C9: MetaClaude | D9: 6717 | E9: 1947 | F9: 71 | G9: 5 | H9: 0 | I9: 0
A10: 46184 | B10: Meta | C10: Metaウェビナー | D10: 4458 | E10: 1593 | F10: 33 | G10: 5 | H10: 0 | I10: 0
A11: 46184 | B11: Meta | C11: Meta介護校 | D11: 17023 | E11: 2691 | F11: 69 | G11: 1 | H11: 0 | I11: 0
A12: 46184 | B12: Meta | C12: MetaClaude | D12: 5818 | E12: 2786 | F12: 66 | G12: 6 | H12: 0 | I12: 0
A13: 46185 | B13: Meta | C13: Meta介護校 | D13: 13326 | E13: 2397 | F13: 68 | G13: 0 | H13: 0 | I13: 0
A14: 46185 | B14: Meta | C14: MetaClaude | D14: 5709 | E14: 3051 | F14: 83 | G14: 2 | H14: 0 | I14: 0
A15: 46186 | B15: Meta | C15: Meta介護校 | D15: 12008 | E15: 2083 | F15: 37 | G15: 5 | H15: 0 | I15: 0
... A41: 46195 | B41: Meta | C41: MetaClaude | D41: 3989 | E41: 1504 | F41: 33 | G41: 1 | H41: 0 | I41: 0

Sheet 週次_媒体別CP
A1: 週次分析：媒体 × キャンペーン別（表側＝時系列）
A2: W1〜W9は確定値。W10以降（緑セル）は『日次入力』タブから自動集計。CPM〜余裕倍率は自動計算。
A4: Meta ／ ウェビナー告知用 （目標CPL ¥3,000）
A5: 週 | B5: 期間 | C5: 消費金額 | D5: IMP | E5: クリック | F5: CV | G5: CTR | H5: CPC | I5: CPM | J5: CVR | K5: CPL | L5: 商談 | M5: 歩留まり | N5: 成約 | O5: 成約率 | P5: 1成約広告費 | Q5: 対許容CPA | R5: 余裕倍率
A6: W1 | B6: 4/7–4/13 | C6: 87849 | D6: 38081 | E6: 612 | F6: 35 | G6: =IFERROR(E6/D6,"") -> 0.016071007 | H6: =IFERROR(C6/E6,"") -> 143.54412 | I6: =IFERROR(C6/D6*1000,"") -> 2306.8985 | J6: =IFERROR(F6/E6,"") -> 0.057189542 | K6: =IFERROR(C6/F6,"") -> 2509.9714 | M6: =IF(L6="","",IFERROR(L6/F6,"")) | O6: =IF(N6="","",IFERROR(N6/L6,"")) | P6: =IF(N6=0,"",IFERROR(C6/N6,"")) | Q6: =IF(N6=0,"",IFERROR(IF(C6/N6<=用語集!$B$22,"◎ 許容内","✗ 超過"),"—")) | R6: =IFERROR(用語集!$B$22/P6,"")
A7: W2 | B7: 4/14–4/20 | C7: 84574 | D7: 32897 | E7: 528 | F7: 34 | G7: =IFERROR(E7/D7,"") -> 0.016050096 | H7: =IFERROR(C7/E7,"") -> 160.17803 | I7: =IFERROR(C7/D7*1000,"") -> 2570.8727 | J7: =IFERROR(F7/E7,"") -> 0.064393939 | K7: =IFERROR(C7/F7,"") -> 2487.4706 | M7: =IF(L7="","",IFERROR(L7/F7,"")) | O7: =IF(N7="","",IFERROR(N7/L7,"")) | P7: =IF(N7=0,"",IFERROR(C7/N7,"")) | Q7: =IF(N7=0,"",IFERROR(IF(C7/N7<=用語集!$B$22,"◎ 許容内","✗ 超過"),"—")) | R7: =IFERROR(用語集!$B$22/P7,"")
A8: W3 | B8: 4/21–4/27 | C8: 77500 | D8: 22541 | E8: 461 | F8: 25 | G8: =IFERROR(E8/D8,"") -> 0.020451621 | H8: =IFERROR(C8/E8,"") -> 168.1128 | I8: =IFERROR(C8/D8*1000,"") -> 3438.1793 | J8: =IFERROR(F8/E8,"") -> 0.054229935 | K8: =IFERROR(C8/F8,"") -> 3100 | M8: =IF(L8="","",IFERROR(L8/F8,"")) | O8: =IF(N8="","",IFERROR(N8/L8,"")) | P8: =IF(N8=0,"",IFERROR(C8/N8,"")) | Q8: =IF(N8=0,"",IFERROR(IF(C8/N8<=用語集!$B$22,"◎ 許容内","✗ 超過"),"—")) | R8: =IFERROR(用語集!$B$22/P8,"")
A9: W4 | B9: 4/28–5/4 | C9: 配信なし | G9: =IFERROR(E9/D9,"") | H9: =IFERROR(C9/E9,"") | I9: =IFERROR(C9/D9*1000,"") | J9: =IFERROR(F9/E9,"") | K9: =IFERROR(C9/F9,"") | M9: =IF(L9="","",IFERROR(L9/F9,"")) | O9: =IF(N9="","",IFERROR(N9/L9,"")) | P9: =IF(N9=0,"",IFERROR(C9/N9,"")) | Q9: =IF(N9=0,"",IFERROR(IF(C9/N9<=用語集!$B$22,"◎ 許容内","✗ 超過"),"—")) | R9: =IFERROR(用語集!$B$22/P9,"")
A10: W5 | B10: 5/5–5/11 | C10: 配信なし | G10: =IFERROR(E10/D10,"") | H10: =IFERROR(C10/E10,"") | I10: =IFERROR(C10/D10*1000,"") | J10: =IFERROR(F10/E10,"") | K10: =IFERROR(C10/F10,"") | M10: =IF(L10="","",IFERROR(L10/F10,"")) | O10: =IF(N10="","",IFERROR(N10/L10,"")) | P10: =IF(N10=0,"",IFERROR(C10/N10,"")) | Q10: =IF(N10=0,"",IFERROR(IF(C10/N10<=用語集!$B$22,"◎ 許容内","✗ 超過"),"—")) | R10: =IFERROR(用語集!$B$22/P10,"")
A11: W6 | B11: 5/12–5/18 | C11: 配信なし | G11: =IFERROR(E11/D11,"") | H11: =IFERROR(C11/E11,"") | I11: =IFERROR(C11/D11*1000,"") | J11: =IFERROR(F11/E11,"") | K11: =IFERROR(C11/F11,"") | M11: =IF(L11="","",IFERROR(L11/F11,"")) | O11: =IF(N11="","",IFERROR(N11/L11,"")) | P11: =IF(N11=0,"",IFERROR(C11/N11,"")) | Q11: =IF(N11=0,"",IFERROR(IF(C11/N11<=用語集!$B$22,"◎ 許容内","✗ 超過"),"—")) | R11: =IFERROR(用語集!$B$22/P11,"")
A12: W7 | B12: 5/19–5/25 | C12: 配信なし | G12: =IFERROR(E12/D12,"") | H12: =IFERROR(C12/E12,"") | I12: =IFERROR(C12/D12*1000,"") | J12: =IFERROR(F12/E12,"") | K12: =IFERROR(C12/F12,"") | M12: =IF(L12="","",IFERROR(L12/F12,"")) | O12: =IF(N12="","",IFERROR(N12/L12,"")) | P12: =IF(N12=0,"",IFERROR(C12/N12,"")) | Q12: =IF(N12=0,"",IFERROR(IF(C12/N12<=用語集!$B$22,"◎ 許容内","✗ 超過"),"—")) | R12: =IFERROR(用語集!$B$22/P12,"")
A13: W8 | B13: 5/26–6/1 | C13: 63871 | D13: 18209 | E13: 469 | F13: 49 | G13: =IFERROR(E13/D13,"") -> 0.025756494 | H13: =IFERROR(C13/E13,"") -> 136.1855 | I13: =IFERROR(C13/D13*1000,"") -> 3507.661 | J13: =IFERROR(F13/E13,"") -> 0.10447761 | K13: =IFERROR(C13/F13,"") -> 1303.4898 | M13: =IF(L13="","",IFERROR(L13/F13,"")) | O13: =IF(N13="","",IFERROR(N13/L13,"")) | P13: =IF(N13=0,"",IFERROR(C13/N13,"")) | Q13: =IF(N13=0,"",IFERROR(IF(C13/N13<=用語集!$B$22,"◎ 許容内","✗ 超過"),"—")) | R13: =IFERROR(用語集!$B$22/P13,"")
A14: W9 | B14: 6/2–6/8 | C14: 103281 | D14: 40922 | E14: 649 | F14: 68 | G14: =IFERROR(E14/D14,"") -> 0.01585944 | H14: =IFERROR(C14/E14,"") -> 159.13867 | I14: =IFERROR(C14/D14*1000,"") -> 2523.8503 | J14: =IFERROR(F14/E14,"") -> 0.10477658 | K14: =IFERROR(C14/F14,"") -> 1518.8382 | M14: =IF(L14="","",IFERROR(L14/F14,"")) | O14: =IF(N14="","",IFERROR(N14/L14,"")) | P14: =IF(N14=0,"",IFERROR(C14/N14,"")) | Q14: =IF(N14=0,"",IFERROR(IF(C14/N14<=用語集!$B$22,"◎ 許容内","✗ 超過"),"—")) | R14: =IFERROR(用語集!$B$22/P14,"")
A15: W10 | B15: 6/9–6/15 | C15: =IF(COUNTIFS(日次入力!$A$4:$A$1500,">="&DATE(2026,6,9),日次入力!$A$4:$A$1500,"<="&DATE(2026,6,15),日次入力!$C$4:$C$1500,"Metaウェビナー")=0,"",SUMIFS(日次入力!$D$4:$D$1500,日次入力!$A$4:$A$1500,">="&DATE(2026,6,9),日次入力!$A$4:$A$1500,"<="&DATE(2026,6,15),日次入力!$C$4:$C$1500,"Metaウェビナー")) -> 36717 | D15: =IF(COUNTIFS(日次入力!$A$4:$A$1500,">="&DATE(2026,6,9),日次入力!$A$4:$A$1500,"<="&DATE(2026,6,15),日次入力!$C$4:$C$1500,"Metaウェビナー")=0,"",SUMIFS(日次入力!$E$4:$E$1500,日次入力!$A$4:$A$1500,">="&DATE(2026,6,9),日次入力!$A$4:$A$1500,"<="&DATE(2026,6,15),日次入力!$C$4:$C$1500,"Metaウェビナー")) -> 12817 | E15: =IF(COUNTIFS(日次入力!$A$4:$A$1500,">="&DATE(2026,6,9),日次入力!$A$4:$A$1500,"<="&DATE(2026,6,15),日次入力!$C$4:$C$1500,"Metaウェビナー")=0,"",SUMIFS(日次入力!$F$4:$F$1500,日次入力!$A$4:$A$1500,">="&DATE(2026,6,9),日次入力!$A$4:$A$1500,"<="&DATE(2026,6,15),日次入力!$C$4:$C$1500,"Metaウェビナー")) -> 232 | F15: =IF(COUNTIFS(日次入力!$A$4:$A$1500,">="&DATE(2026,6,9),日次入力!$A$4:$A$1500,"<="&DATE(2026,6,15),日次入力!$C$4:$C$1500,"Metaウェビナー")=0,"",SUMIFS(日次入力!$G$4:$G$1500,日次入力!$A$4:$A$1500,">="&DATE(2026,6,9),日次入力!$A$4:$A$1500,"<="&DATE(2026,6,15),日次入力!$C$4:$C$1500,"Metaウェビナー")) -> 33 | G15: =IFERROR(E15/D15,"") -> 0.01810096 | H15: =IFERROR(C15/E15,"") -> 158.26293 | I15: =IFERROR(C15/D15*1000,"") -> 2864.7109 | J15: =IFERROR(F15/E15,"") -> 0.14224138 | K15: =IFERROR(C15/F15,"") -> 1112.6364 | L15: =IF(COUNTIFS(日次入力!$A$4:$A$1500,">="&DATE(2026,6,9),日次入力!$A$4:$A$1500,"<="&DATE(2026,6,15),日次入力!$C$4:$C$1500,"Metaウェビナー")=0,"",SUMIFS(日次入力!$H$4:$H$1500,日次入力!$A$4:$A$1500,">="&DATE(2026,6,9),日次入力!$A$4:$A$1500,"<="&DATE(2026,6,15),日次入力!$C$4:$C$1500,"Metaウェビナー")) -> 0 | M15: =IF(L15="","",IFERROR(L15/F15,"")) -> 0 | N15: =IF(COUNTIFS(日次入力!$A$4:$A$1500,">="&DATE(2026,6,9),日次入力!$A$4:$A$1500,"<="&DATE(2026,6,15),日次入力!$C$4:$C$1500,"Metaウェビナー")=0,"",SUMIFS(日次入力!$I$4:$I$1500,日次入力!$A$4:$A$1500,">="&DATE(2026,6,9),日次入力!$A$4:$A$1500,"<="&DATE(2026,6,15),日次入力!$C$4:$C$1500,"Metaウェビナー")) -> 0 | O15: =IF(N15="","",IFERROR(N15/L15,"")) | P15: =IF(N15=0,"",IFERROR(C15/N15,"")) | Q15: =IF(N15=0,"",IFERROR(IF(C15/N15<=用語集!$B$22,"◎ 許容内","✗ 超過"),"—")) | R15: =IFERROR(用語集!$B$22/P15,"")
A16: W11 | B16: 6/16–6/22 | C16: =IF(COUNTIFS(日次入力!$A$4:$A$1500,">="&DATE(2026,6,16),日次入力!$A$4:$A$1500,"<="&DATE(2026,6,22),日次入力!$C$4:$C$1500,"Metaウェビナー")=0,"",SUMIFS(日次入力!$D$4:$D$1500,日次入力!$A$4:$A$1500,">="&DATE(2026,6,16),日次入力!$A$4:$A$1500,"<="&DATE(2026,6,22),日次入力!$C$4:$C$1500,"Metaウェビナー")) -> 91426 | D16: =IF(COUNTIFS(日次入力!$A$4:$A$1500,">="&DATE(2026,6,16),日次入力!$A$4:$A$1500,"<="&DATE(2026,6,22),日次入力!$C$4:$C$1500,"Metaウェビナー")=0,"",SUMIFS(日次入力!$E$4:$E$1500,日次入力!$A$4:$A$1500,">="&DATE(2026,6,16),日次入力!$A$4:$A$1500,"<="&DATE(2026,6,22),日次入力!$C$4:$C$1500,"Metaウェビナー")) -> 31765 | E16: =IF(COUNTIFS(日次入力!$A$4:$A$1500,">="&DATE(2026,6,16),日次入力!$A$4:$A$1500,"<="&DATE(2026,6,22),日次入力!$C$4:$C$1500,"Metaウェビナー")=0,"",SUMIFS(日次入力!$F$4:$F$1500,日次入力!$A$4:$A$1500,">="&DATE(2026,6,16),日次入力!$A$4:$A$1500,"<="&DATE(2026,6,22),日次入力!$C$4:$C$1500,"Metaウェビナー")) -> 461 | F16: =IF(COUNTIFS(日次入力!$A$4:$A$1500,">="&DATE(2026,6,16),日次入力!$A$4:$A$1500,"<="&DATE(2026,6,22),日次入力!$C$4:$C$1500,"Metaウェビナー")=0,"",SUMIFS(日次入力!$G$4:$G$1500,日次入力!$A$4:$A$1500,">="&DATE(2026,6,16),日次入力!$A$4:$A$1500,"<="&DATE(2026,6,22),日次入力!$C$4:$C$1500,"Metaウェビナー")) -> 28 | G16: =IFERROR(E16/D16,"") -> 0.014512829 | H16: =IFERROR(C16/E16,"") -> 198.32104 | I16: =IFERROR(C16/D16*1000,"") -> 2878.1993 | J16: =IFERROR(F16/E16,"") -> 0.060737527 | K16: =IFERROR(C16/F16,"") -> 3265.2143 | L16: =IF(COUNTIFS(日次入力!$A$4:$A$1500,">="&DATE(2026,6,16),日次入力!$A$4:$A$1500,"<="&DATE(2026,6,22),日次入力!$C$4:$C$1500,"Metaウェビナー")=0,"",SUMIFS(日次入力!$H$4:$H$1500,日次入力!$A$4:$A$1500,">="&DATE(2026,6,16),日次入力!$A$4:$A$1500,"<="&DATE(2026,6,22),日次入力!$C$4:$C$1500,"Metaウェビナー")) -> 3 | M16: =IF(L16="","",IFERROR(L16/F16,"")) -> 0.10714286 | N16: =IF(COUNTIFS(日次入力!$A$4:$A$1500,">="&DATE(2026,6,16),日次入力!$A$4:$A$1500,"<="&DATE(2026,6,22),日次入力!$C$4:$C$1500,"Metaウェビナー")=0,"",SUMIFS(日次入力!$I$4:$I$1500,日次入力!$A$4:$A$1500,">="&DATE(2026,6,16),日次入力!$A$4:$A$1500,"<="&DATE(2026,6,22),日次入力!$C$4:$C$1500,"Metaウェビナー")) -> 0 | O16: =IF(N16="","",IFERROR(N16/L16,"")) -> 0 | P16: =IF(N16=0,"",IFERROR(C16/N16,"")) | Q16: =IF(N16=0,"",IFERROR(IF(C16/N16<=用語集!$B$22,"◎ 許容内","✗ 超過"),"—")) | R16: =IFERROR(用語集!$B$22/P16,"")
A17: W12 | B17: 6/23–6/29 | C17: =IF(COUNTIFS(日次入力!$A$4:$A$1500,">="&DATE(2026,6,23),日次入力!$A$4:$A$1500,"<="&DATE(2026,6,29),日次入力!$C$4:$C$1500,"Metaウェビナー")=0,"",SUMIFS(日次入力!$D$4:$D$1500,日次入力!$A$4:$A$1500,">="&DATE(2026,6,23),日次入力!$A$4:$A$1500,"<="&DATE(2026,6,29),日次入力!$C$4:$C$1500,"Metaウェビナー")) | D17: =IF(COUNTIFS(日次入力!$A$4:$A$1500,">="&DATE(2026,6,23),日次入力!$A$4:$A$1500,"<="&DATE(2026,6,29),日次入力!$C$4:$C$1500,"Metaウェビナー")=0,"",SUMIFS(日次入力!$E$4:$E$1500,日次入力!$A$4:$A$1500,">="&DATE(2026,6,23),日次入力!$A$4:$A$1500,"<="&DATE(2026,6,29),日次入力!$C$4:$C$1500,"Metaウェビナー")) | E17: =IF(COUNTIFS(日次入力!$A$4:$A$1500,">="&DATE(2026,6,23),日次入力!$A$4:$A$1500,"<="&DATE(2026,6,29),日次入力!$C$4:$C$1500,"Metaウェビナー")=0,"",SUMIFS(日次入力!$F$4:$F$1500,日次入力!$A$4:$A$1500,">="&DATE(2026,6,23),日次入力!$A$4:$A$1500,"<="&DATE(2026,6,29),日次入力!$C$4:$C$1500,"Metaウェビナー")) | F17: =IF(COUNTIFS(日次入力!$A$4:$A$1500,">="&DATE(2026,6,23),日次入力!$A$4:$A$1500,"<="&DATE(2026,6,29),日次入力!$C$4:$C$1500,"Metaウェビナー")=0,"",SUMIFS(日次入力!$G$4:$G$1500,日次入力!$A$4:$A$1500,">="&DATE(2026,6,23),日次入力!$A$4:$A$1500,"<="&DATE(2026,6,29),日次入力!$C$4:$C$1500,"Metaウェビナー")) | G17: =IFERROR(E17/D17,"") | H17: =IFERROR(C17/E17,"") | I17: =IFERROR(C17/D17*1000,"") | J17: =IFERROR(F17/E17,"") | K17: =IFERROR(C17/F17,"") | L17: =IF(COUNTIFS(日次入力!$A$4:$A$1500,">="&DATE(2026,6,23),日次入力!$A$4:$A$1500,"<="&DATE(2026,6,29),日次入力!$C$4:$C$1500,"Metaウェビナー")=0,"",SUMIFS(日次入力!$H$4:$H$1500,日次入力!$A$4:$A$1500,">="&DATE(2026,6,23),日次入力!$A$4:$A$1500,"<="&DATE(2026,6,29),日次入力!$C$4:$C$1500,"Metaウェビナー")) | M17: =IF(L17="","",IFERROR(L17/F17,"")) | N17: =IF(COUNTIFS(日次入力!$A$4:$A$1500,">="&DATE(2026,6,23),日次入力!$A$4:$A$1500,"<="&DATE(2026,6,29),日次入力!$C$4:$C$1500,"Metaウェビナー")=0,"",SUMIFS(日次入力!$I$4:$I$1500,日次入力!$A$4:$A$1500,">="&DATE(2026,6,23),日次入力!$A$4:$A$1500,"<="&DATE(2026,6,29),日次入力!$C$4:$C$1500,"Metaウェビナー")) | O17: =IF(N17="","",IFERROR(N17/L17,"")) | P17: =IF(N17=0,"",IFERROR(C17/N17,"")) | Q17: =IF(N17=0,"",IFERROR(IF(C17/N17<=用語集!$B$22,"◎ 許容内","✗ 超過"),"—")) -> — | R17: =IFERROR(用語集!$B$22/P17,"")
A18: W13 | B18: 6/30–7/6 | C18: =IF(COUNTIFS(日次入力!$A$4:$A$1500,">="&DATE(2026,6,30),日次入力!$A$4:$A$1500,"<="&DATE(2026,7,6),日次入力!$C$4:$C$1500,"Metaウェビナー")=0,"",SUMIFS(日次入力!$D$4:$D$1500,日次入力!$A$4:$A$1500,">="&DATE(2026,6,30),日次入力!$A$4:$A$1500,"<="&DATE(2026,7,6),日次入力!$C$4:$C$1500,"Metaウェビナー")) | D18: =IF(COUNTIFS(日次入力!$A$4:$A$1500,">="&DATE(2026,6,30),日次入力!$A$4:$A$1500,"<="&DATE(2026,7,6),日次入力!$C$4:$C$1500,"Metaウェビナー")=0,"",SUMIFS(日次入力!$E$4:$E$1500,日次入力!$A$4:$A$1500,">="&DATE(2026,6,30),日次入力!$A$4:$A$1500,"<="&DATE(2026,7,6),日次入力!$C$4:$C$1500,"Metaウェビナー")) | E18: =IF(COUNTIFS(日次入力!$A$4:$A$1500,">="&DATE(2026,6,30),日次入力!$A$4:$A$1500,"<="&DATE(2026,7,6),日次入力!$C$4:$C$1500,"Metaウェビナー")=0,"",SUMIFS(日次入力!$F$4:$F$1500,日次入力!$A$4:$A$1500,">="&DATE(2026,6,30),日次入力!$A$4:$A$1500,"<="&DATE(2026,7,6),日次入力!$C$4:$C$1500,"Metaウェビナー")) | F18: =IF(COUNTIFS(日次入力!$A$4:$A$1500,">="&DATE(2026,6,30),日次入力!$A$4:$A$1500,"<="&DATE(2026,7,6),日次入力!$C$4:$C$1500,"Metaウェビナー")=0,"",SUMIFS(日次入力!$G$4:$G$1500,日次入力!$A$4:$A$1500,">="&DATE(2026,6,30),日次入力!$A$4:$A$1500,"<="&DATE(2026,7,6),日次入力!$C$4:$C$1500,"Metaウェビナー")) | G18: =IFERROR(E18/D18,"") | H18: =IFERROR(C18/E18,"") | I18: =IFERROR(C18/D18*1000,"") | J18: =IFERROR(F18/E18,"") | K18: =IFERROR(C18/F18,"") | L18: =IF(COUNTIFS(日次入力!$A$4:$A$1500,">="&DATE(2026,6,30),日次入力!$A$4:$A$1500,"<="&DATE(2026,7,6),日次入力!$C$4:$C$1500,"Metaウェビナー")=0,"",SUMIFS(日次入力!$H$4:$H$1500,日次入力!$A$4:$A$1500,">="&DATE(2026,6,30),日次入力!$A$4:$A$1500,"<="&DATE(2026,7,6),日次入力!$C$4:$C$1500,"Metaウェビナー")) | M18: =IF(L18="","",IFERROR(L18/F18,"")) | N18: =IF(COUNTIFS(日次入力!$A$4:$A$1500,">="&DATE(2026,6,30),日次入力!$A$4:$A$1500,"<="&DATE(2026,7,6),日次入力!$C$4:$C$1500,"Metaウェビナー")=0,"",SUMIFS(日次入力!$I$4:$I$1500,日次入力!$A$4:$A$1500,">="&DATE(2026,6,30),日次入力!$A$4:$A$1500,"<="&DATE(2026,7,6),日次入力!$C$4:$C$1500,"Metaウェビナー")) | O18: =IF(N18="","",IFERROR(N18/L18,"")) | P18: =IF(N18=0,"",IFERROR(C18/N18,"")) | Q18: =IF(N18=0,"",IFERROR(IF(C18/N18<=用語集!$B$22,"◎ 許容内","✗ 超過"),"—")) -> — | R18: =IFERROR(用語集!$B$22/P18,"")
A19: W14 | B19: 7/7–7/13 | C19: =IF(COUNTIFS(日次入力!$A$4:$A$1500,">="&DATE(2026,7,7),日次入力!$A$4:$A$1500,"<="&DATE(2026,7,13),日次入力!$C$4:$C$1500,"Metaウェビナー")=0,"",SUMIFS(日次入力!$D$4:$D$1500,日次入力!$A$4:$A$1500,">="&DATE(2026,7,7),日次入力!$A$4:$A$1500,"<="&DATE(2026,7,13),日次入力!$C$4:$C$1500,"Metaウェビナー")) | D19: =IF(COUNTIFS(日次入力!$A$4:$A$1500,">="&DATE(2026,7,7),日次入力!$A$4:$A$1500,"<="&DATE(2026,7,13),日次入力!$C$4:$C$1500,"Metaウェビナー")=0,"",SUMIFS(日次入力!$E$4:$E$1500,日次入力!$A$4:$A$1500,">="&DATE(2026,7,7),日次入力!$A$4:$A$1500,"<="&DATE(2026,7,13),日次入力!$C$4:$C$1500,"Metaウェビナー")) | E19: =IF(COUNTIFS(日次入力!$A$4:$A$1500,">="&DATE(2026,7,7),日次入力!$A$4:$A$1500,"<="&DATE(2026,7,13),日次入力!$C$4:$C$1500,"Metaウェビナー")=0,"",SUMIFS(日次入力!$F$4:$F$1500,日次入力!$A$4:$A$1500,">="&DATE(2026,7,7),日次入力!$A$4:$A$1500,"<="&DATE(2026,7,13),日次入力!$C$4:$C$1500,"Metaウェビナー")) | F19: =IF(COUNTIFS(日次入力!$A$4:$A$1500,">="&DATE(2026,7,7),日次入力!$A$4:$A$1500,"<="&DATE(2026,7,13),日次入力!$C$4:$C$1500,"Metaウェビナー")=0,"",SUMIFS(日次入力!$G$4:$G$1500,日次入力!$A$4:$A$1500,">="&DATE(2026,7,7),日次入力!$A$4:$A$1500,"<="&DATE(2026,7,13),日次入力!$C$4:$C$1500,"Metaウェビナー")) | G19: =IFERROR(E19/D19,"") | H19: =IFERROR(C19/E19,"") | I19: =IFERROR(C19/D19*1000,"") | J19: =IFERROR(F19/E19,"") | K19: =IFERROR(C19/F19,"") | L19: =IF(COUNTIFS(日次入力!$A$4:$A$1500,">="&DATE(2026,7,7),日次入力!$A$4:$A$1500,"<="&DATE(2026,7,13),日次入力!$C$4:$C$1500,"Metaウェビナー")=0,"",SUMIFS(日次入力!$H$4:$H$1500,日次入力!$A$4:$A$1500,">="&DATE(2026,7,7),日次入力!$A$4:$A$1500,"<="&DATE(2026,7,13),日次入力!$C$4:$C$1500,"Metaウェビナー")) | M19: =IF(L19="","",IFERROR(L19/F19,"")) | N19: =IF(COUNTIFS(日次入力!$A$4:$A$1500,">="&DATE(2026,7,7),日次入力!$A$4:$A$1500,"<="&DATE(2026,7,13),日次入力!$C$4:$C$1500,"Metaウェビナー")=0,"",SUMIFS(日次入力!$I$4:$I$1500,日次入力!$A$4:$A$1500,">="&DATE(2026,7,7),日次入力!$A$4:$A$1500,"<="&DATE(2026,7,13),日次入力!$C$4:$C$1500,"Metaウェビナー")) | O19: =IF(N19="","",IFERROR(N19/L19,"")) | P19: =IF(N19=0,"",IFERROR(C19/N19,"")) | Q19: =IF(N19=0,"",IFERROR(IF(C19/N19<=用語集!$B$22,"◎ 許容内","✗ 超過"),"—")) -> — | R19: =IFERROR(用語集!$B$22/P19,"")
A20: W15 | B20: 7/14–7/20 | C20: =IF(COUNTIFS(日次入力!$A$4:$A$1500,">="&DATE(2026,7,14),日次入力!$A$4:$A$1500,"<="&DATE(2026,7,20),日次入力!$C$4:$C$1500,"Metaウェビナー")=0,"",SUMIFS(日次入力!$D$4:$D$1500,日次入力!$A$4:$A$1500,">="&DATE(2026,7,14),日次入力!$A$4:$A$1500,"<="&DATE(2026,7,20),日次入力!$C$4:$C$1500,"Metaウェビナー")) | D20: =IF(COUNTIFS(日次入力!$A$4:$A$1500,">="&DATE(2026,7,14),日次入力!$A$4:$A$1500,"<="&DATE(2026,7,20),日次入力!$C$4:$C$1500,"Metaウェビナー")=0,"",SUMIFS(日次入力!$E$4:$E$1500,日次入力!$A$4:$A$1500,">="&DATE(2026,7,14),日次入力!$A$4:$A$1500,"<="&DATE(2026,7,20),日次入力!$C$4:$C$1500,"Metaウェビナー")) | E20: =IF(COUNTIFS(日次入力!$A$4:$A$1500,">="&DATE(2026,7,14),日次入力!$A$4:$A$1500,"<="&DATE(2026,7,20),日次入力!$C$4:$C$1500,"Metaウェビナー")=0,"",SUMIFS(日次入力!$F$4:$F$1500,日次入力!$A$4:$A$1500,">="&DATE(2026,7,14),日次入力!$A$4:$A$1500,"<="&DATE(2026,7,20),日次入力!$C$4:$C$1500,"Metaウェビナー")) | F20: =IF(COUNTIFS(日次入力!$A$4:$A$1500,">="&DATE(2026,7,14),日次入力!$A$4:$A$1500,"<="&DATE(2026,7,20),日次入力!$C$4:$C$1500,"Metaウェビナー")=0,"",SUMIFS(日次入力!$G$4:$G$1500,日次入力!$A$4:$A$1500,">="&DATE(2026,7,14),日次入力!$A$4:$A$1500,"<="&DATE(2026,7,20),日次入力!$C$4:$C$1500,"Metaウェビナー")) | G20: =IFERROR(E20/D20,"") | H20: =IFERROR(C20/E20,"") | I20: =IFERROR(C20/D20*1000,"") | J20: =IFERROR(F20/E20,"") | K20: =IFERROR(C20/F20,"") | L20: =IF(COUNTIFS(日次入力!$A$4:$A$1500,">="&DATE(2026,7,14),日次入力!$A$4:$A$1500,"<="&DATE(2026,7,20),日次入力!$C$4:$C$1500,"Metaウェビナー")=0,"",SUMIFS(日次入力!$H$4:$H$1500,日次入力!$A$4:$A$1500,">="&DATE(2026,7,14),日次入力!$A$4:$A$1500,"<="&DATE(2026,7,20),日次入力!$C$4:$C$1500,"Metaウェビナー")) | M20: =IF(L20="","",IFERROR(L20/F20,"")) | N20: =IF(COUNTIFS(日次入力!$A$4:$A$1500,">="&DATE(2026,7,14),日次入力!$A$4:$A$1500,"<="&DATE(2026,7,20),日次入力!$C$4:$C$1500,"Metaウェビナー")=0,"",SUMIFS(日次入力!$I$4:$I$1500,日次入力!$A$4:$A$1500,">="&DATE(2026,7,14),日次入力!$A$4:$A$1500,"<="&DATE(2026,7,20),日次入力!$C$4:$C$1500,"Metaウェビナー")) | O20: =IF(N20="","",IFERROR(N20/L20,"")) | P20: =IF(N20=0,"",IFERROR(C20/N20,"")) | Q20: =IF(N20=0,"",IFERROR(IF(C20/N20<=用語集!$B$22,"◎ 許容内","✗ 超過"),"—")) -> — | R20: =IFERROR(用語集!$B$22/P20,"")
A21: W16 | B21: 7/21–7/27 | C21: =IF(COUNTIFS(日次入力!$A$4:$A$1500,">="&DATE(2026,7,21),日次入力!$A$4:$A$1500,"<="&DATE(2026,7,27),日次入力!$C$4:$C$1500,"Metaウェビナー")=0,"",SUMIFS(日次入力!$D$4:$D$1500,日次入力!$A$4:$A$1500,">="&DATE(2026,7,21),日次入力!$A$4:$A$1500,"<="&DATE(2026,7,27),日次入力!$C$4:$C$1500,"Metaウェビナー")) | D21: =IF(COUNTIFS(日次入力!$A$4:$A$1500,">="&DATE(2026,7,21),日次入力!$A$4:$A$1500,"<="&DATE(2026,7,27),日次入力!$C$4:$C$1500,"Metaウェビナー")=0,"",SUMIFS(日次入力!$E$4:$E$1500,日次入力!$A$4:$A$1500,">="&DATE(2026,7,21),日次入力!$A$4:$A$1500,"<="&DATE(2026,7,27),日次入力!$C$4:$C$1500,"Metaウェビナー")) | E21: =IF(COUNTIFS(日次入力!$A$4:$A$1500,">="&DATE(2026,7,21),日次入力!$A$4:$A$1500,"<="&DATE(2026,7,27),日次入力!$C$4:$C$1500,"Metaウェビナー")=0,"",SUMIFS(日次入力!$F$4:$F$1500,日次入力!$A$4:$A$1500,">="&DATE(2026,7,21),日次入力!$A$4:$A$1500,"<="&DATE(2026,7,27),日次入力!$C$4:$C$1500,"Metaウェビナー")) | F21: =IF(COUNTIFS(日次入力!$A$4:$A$1500,">="&DATE(2026,7,21),日次入力!$A$4:$A$1500,"<="&DATE(2026,7,27),日次入力!$C$4:$C$1500,"Metaウェビナー")=0,"",SUMIFS(日次入力!$G$4:$G$1500,日次入力!$A$4:$A$1500,">="&DATE(2026,7,21),日次入力!$A$4:$A$1500,"<="&DATE(2026,7,27),日次入力!$C$4:$C$1500,"Metaウェビナー")) | G21: =IFERROR(E21/D21,"") | H21: =IFERROR(C21/E21,"") | I21: =IFERROR(C21/D21*1000,"") | J21: =IFERROR(F21/E21,"") | K21: =IFERROR(C21/F21,"") | L21: =IF(COUNTIFS(日次入力!$A$4:$A$1500,">="&DATE(2026,7,21),日次入力!$A$4:$A$1500,"<="&DATE(2026,7,27),日次入力!$C$4:$C$1500,"Metaウェビナー")=0,"",SUMIFS(日次入力!$H$4:$H$1500,日次入力!$A$4:$A$1500,">="&DATE(2026,7,21),日次入力!$A$4:$A$1500,"<="&DATE(2026,7,27),日次入力!$C$4:$C$1500,"Metaウェビナー")) | M21: =IF(L21="","",IFERROR(L21/F21,"")) | N21: =IF(COUNTIFS(日次入力!$A$4:$A$1500,">="&DATE(2026,7,21),日次入力!$A$4:$A$1500,"<="&DATE(2026,7,27),日次入力!$C$4:$C$1500,"Metaウェビナー")=0,"",SUMIFS(日次入力!$I$4:$I$1500,日次入力!$A$4:$A$1500,">="&DATE(2026,7,21),日次入力!$A$4:$A$1500,"<="&DATE(2026,7,27),日次入力!$C$4:$C$1500,"Metaウェビナー")) | O21: =IF(N21="","",IFERROR(N21/L21,"")) | P21: =IF(N21=0,"",IFERROR(C21/N21,"")) | Q21: =IF(N21=0,"",IFERROR(IF(C21/N21<=用語集!$B$22,"◎ 許容内","✗ 超過"),"—")) -> — | R21: =IFERROR(用語集!$B$22/P21,"")
A22: W17 | B22: 7/28–8/3 | C22: =IF(COUNTIFS(日次入力!$A$4:$A$1500,">="&DATE(2026,7,28),日次入力!$A$4:$A$1500,"<="&DATE(2026,8,3),日次入力!$C$4:$C$1500,"Metaウェビナー")=0,"",SUMIFS(日次入力!$D$4:$D$1500,日次入力!$A$4:$A$1500,">="&DATE(2026,7,28),日次入力!$A$4:$A$1500,"<="&DATE(2026,8,3),日次入力!$C$4:$C$1500,"Metaウェビナー")) | D22: =IF(COUNTIFS(日次入力!$A$4:$A$1500,">="&DATE(2026,7,28),日次入力!$A$4:$A$1500,"<="&DATE(2026,8,3),日次入力!$C$4:$C$1500,"Metaウェビナー")=0,"",SUMIFS(日次入力!$E$4:$E$1500,日次入力!$A$4:$A$1500,">="&DATE(2026,7,28),日次入力!$A$4:$A$1500,"<="&DATE(2026,8,3),日次入力!$C$4:$C$1500,"Metaウェビナー")) | E22: =IF(COUNTIFS(日次入力!$A$4:$A$1500,">="&DATE(2026,7,28),日次入力!$A$4:$A$1500,"<="&DATE(2026,8,3),日次入力!$C$4:$C$1500,"Metaウェビナー")=0,"",SUMIFS(日次入力!$F$4:$F$1500,日次入力!$A$4:$A$1500,">="&DATE(2026,7,28),日次入力!$A$4:$A$1500,"<="&DATE(2026,8,3),日次入力!$C$4:$C$1500,"Metaウェビナー")) | F22: =IF(COUNTIFS(日次入力!$A$4:$A$1500,">="&DATE(2026,7,28),日次入力!$A$4:$A$1500,"<="&DATE(2026,8,3),日次入力!$C$4:$C$1500,"Metaウェビナー")=0,"",SUMIFS(日次入力!$G$4:$G$1500,日次入力!$A$4:$A$1500,">="&DATE(2026,7,28),日次入力!$A$4:$A$1500,"<="&DATE(2026,8,3),日次入力!$C$4:$C$1500,"Metaウェビナー")) | G22: =IFERROR(E22/D22,"") | H22: =IFERROR(C22/E22,"") | I22: =IFERROR(C22/D22*1000,"") | J22: =IFERROR(F22/E22,"") | K22: =IFERROR(C22/F22,"") | L22: =IF(COUNTIFS(日次入力!$A$4:$A$1500,">="&DATE(2026,7,28),日次入力!$A$4:$A$1500,"<="&DATE(2026,8,3),日次入力!$C$4:$C$1500,"Metaウェビナー")=0,"",SUMIFS(日次入力!$H$4:$H$1500,日次入力!$A$4:$A$1500,">="&DATE(2026,7,28),日次入力!$A$4:$A$1500,"<="&DATE(2026,8,3),日次入力!$C$4:$C$1500,"Metaウェビナー")) | M22: =IF(L22="","",IFERROR(L22/F22,"")) | N22: =IF(COUNTIFS(日次入力!$A$4:$A$1500,">="&DATE(2026,7,28),日次入力!$A$4:$A$1500,"<="&DATE(2026,8,3),日次入力!$C$4:$C$1500,"Metaウェビナー")=0,"",SUMIFS(日次入力!$I$4:$I$1500,日次入力!$A$4:$A$1500,">="&DATE(2026,7,28),日次入力!$A$4:$A$1500,"<="&DATE(2026,8,3),日次入力!$C$4:$C$1500,"Metaウェビナー")) | O22: =IF(N22="","",IFERROR(N22/L22,"")) | P22: =IF(N22=0,"",IFERROR(C22/N22,"")) | Q22: =IF(N22=0,"",IFERROR(IF(C22/N22<=用語集!$B$22,"◎ 許容内","✗ 超過"),"—")) -> — | R22: =IFERROR(用語集!$B$22/P22,"")
A23: W18 | B23: 8/4–8/10 | C23: =IF(COUNTIFS(日次入力!$A$4:$A$1500,">="&DATE(2026,8,4),日次入力!$A$4:$A$1500,"<="&DATE(2026,8,10),日次入力!$C$4:$C$1500,"Metaウェビナー")=0,"",SUMIFS(日次入力!$D$4:$D$1500,日次入力!$A$4:$A$1500,">="&DATE(2026,8,4),日次入力!$A$4:$A$1500,"<="&DATE(2026,8,10),日次入力!$C$4:$C$1500,"Metaウェビナー")) | D23: =IF(COUNTIFS(日次入力!$A$4:$A$1500,">="&DATE(2026,8,4),日次入力!$A$4:$A$1500,"<="&DATE(2026,8,10),日次入力!$C$4:$C$1500,"Metaウェビナー")=0,"",SUMIFS(日次入力!$E$4:$E$1500,日次入力!$A$4:$A$1500,">="&DATE(2026,8,4),日次入力!$A$4:$A$1500,"<="&DATE(2026,8,10),日次入力!$C$4:$C$1500,"Metaウェビナー")) | E23: =IF(COUNTIFS(日次入力!$A$4:$A$1500,">="&DATE(2026,8,4),日次入力!$A$4:$A$1500,"<="&DATE(2026,8,10),日次入力!$C$4:$C$1500,"Metaウェビナー")=0,"",SUMIFS(日次入力!$F$4:$F$1500,日次入力!$A$4:$A$1500,">="&DATE(2026,8,4),日次入力!$A$4:$A$1500,"<="&DATE(2026,8,10),日次入力!$C$4:$C$1500,"Metaウェビナー")) | F23: =IF(COUNTIFS(日次入力!$A$4:$A$1500,">="&DATE(2026,8,4),日次入力!$A$4:$A$1500,"<="&DATE(2026,8,10),日次入力!$C$4:$C$1500,"Metaウェビナー")=0,"",SUMIFS(日次入力!$G$4:$G$1500,日次入力!$A$4:$A$1500,">="&DATE(2026,8,4),日次入力!$A$4:$A$1500,"<="&DATE(2026,8,10),日次入力!$C$4:$C$1500,"Metaウェビナー")) | G23: =IFERROR(E23/D23,"") | H23: =IFERROR(C23/E23,"") | I23: =IFERROR(C23/D23*1000,"") | J23: =IFERROR(F23/E23,"") | K23: =IFERROR(C23/F23,"") | L23: =IF(COUNTIFS(日次入力!$A$4:$A$1500,">="&DATE(2026,8,4),日次入力!$A$4:$A$1500,"<="&DATE(2026,8,10),日次入力!$C$4:$C$1500,"Metaウェビナー")=0,"",SUMIFS(日次入力!$H$4:$H$1500,日次入力!$A$4:$A$1500,">="&DATE(2026,8,4),日次入力!$A$4:$A$1500,"<="&DATE(2026,8,10),日次入力!$C$4:$C$1500,"Metaウェビナー")) | M23: =IF(L23="","",IFERROR(L23/F23,"")) | N23: =IF(COUNTIFS(日次入力!$A$4:$A$1500,">="&DATE(2026,8,4),日次入力!$A$4:$A$1500,"<="&DATE(2026,8,10),日次入力!$C$4:$C$1500,"Metaウェビナー")=0,"",SUMIFS(日次入力!$I$4:$I$1500,日次入力!$A$4:$A$1500,">="&DATE(2026,8,4),日次入力!$A$4:$A$1500,"<="&DATE(2026,8,10),日次入力!$C$4:$C$1500,"Metaウェビナー")) | O23: =IF(N23="","",IFERROR(N23/L23,"")) | P23: =IF(N23=0,"",IFERROR(C23/N23,"")) | Q23: =IF(N23=0,"",IFERROR(IF(C23/N23<=用語集!$B$22,"◎ 許容内","✗ 超過"),"—")) -> — | R23: =IFERROR(用語集!$B$22/P23,"")
A24: W19 | B24: 8/11–8/17 | C24: =IF(COUNTIFS(日次入力!$A$4:$A$1500,">="&DATE(2026,8,11),日次入力!$A$4:$A$1500,"<="&DATE(2026,8,17),日次入力!$C$4:$C$1500,"Metaウェビナー")=0,"",SUMIFS(日次入力!$D$4:$D$1500,日次入力!$A$4:$A$1500,">="&DATE(2026,8,11),日次入力!$A$4:$A$1500,"<="&DATE(2026,8,17),日次入力!$C$4:$C$1500,"Metaウェビナー")) | D24: =IF(COUNTIFS(日次入力!$A$4:$A$1500,">="&DATE(2026,8,11),日次入力!$A$4:$A$1500,"<="&DATE(2026,8,17),日次入力!$C$4:$C$1500,"Metaウェビナー")=0,"",SUMIFS(日次入力!$E$4:$E$1500,日次入力!$A$4:$A$1500,">="&DATE(2026,8,11),日次入力!$A$4:$A$1500,"<="&DATE(2026,8,17),日次入力!$C$4:$C$1500,"Metaウェビナー")) | E24: =IF(COUNTIFS(日次入力!$A$4:$A$1500,">="&DATE(2026,8,11),日次入力!$A$4:$A$1500,"<="&DATE(2026,8,17),日次入力!$C$4:$C$1500,"Metaウェビナー")=0,"",SUMIFS(日次入力!$F$4:$F$1500,日次入力!$A$4:$A$1500,">="&DATE(2026,8,11),日次入力!$A$4:$A$1500,"<="&DATE(2026,8,17),日次入力!$C$4:$C$1500,"Metaウェビナー")) | F24: =IF(COUNTIFS(日次入力!$A$4:$A$1500,">="&DATE(2026,8,11),日次入力!$A$4:$A$1500,"<="&DATE(2026,8,17),日次入力!$C$4:$C$1500,"Metaウェビナー")=0,"",SUMIFS(日次入力!$G$4:$G$1500,日次入力!$A$4:$A$1500,">="&DATE(2026,8,11),日次入力!$A$4:$A$1500,"<="&DATE(2026,8,17),日次入力!$C$4:$C$1500,"Metaウェビナー")) | G24: =IFERROR(E24/D24,"") | H24: =IFERROR(C24/E24,"") | I24: =IFERROR(C24/D24*1000,"") | J24: =IFERROR(F24/E24,"") | K24: =IFERROR(C24/F24,"") | L24: =IF(COUNTIFS(日次入力!$A$4:$A$1500,">="&DATE(2026,8,11),日次入力!$A$4:$A$1500,"<="&DATE(2026,8,17),日次入力!$C$4:$C$1500,"Metaウェビナー")=0,"",SUMIFS(日次入力!$H$4:$H$1500,日次入力!$A$4:$A$1500,">="&DATE(2026,8,11),日次入力!$A$4:$A$1500,"<="&DATE(2026,8,17),日次入力!$C$4:$C$1500,"Metaウェビナー")) | M24: =IF(L24="","",IFERROR(L24/F24,"")) | N24: =IF(COUNTIFS(日次入力!$A$4:$A$1500,">="&DATE(2026,8,11),日次入力!$A$4:$A$1500,"<="&DATE(2026,8,17),日次入力!$C$4:$C$1500,"Metaウェビナー")=0,"",SUMIFS(日次入力!$I$4:$I$1500,日次入力!$A$4:$A$1500,">="&DATE(2026,8,11),日次入力!$A$4:$A$1500,"<="&DATE(2026,8,17),日次入力!$C$4:$C$1500,"Metaウェビナー")) | O24: =IF(N24="","",IFERROR(N24/L24,"")) | P24: =IF(N24=0,"",IFERROR(C24/N24,"")) | Q24: =IF(N24=0,"",IFERROR(IF(C24/N24<=用語集!$B$22,"◎ 許容内","✗ 超過"),"—")) -> — | R24: =IFERROR(用語集!$B$22/P24,"")
A25: W20 | B25: 8/18–8/24 | C25: =IF(COUNTIFS(日次入力!$A$4:$A$1500,">="&DATE(2026,8,18),日次入力!$A$4:$A$1500,"<="&DATE(2026,8,24),日次入力!$C$4:$C$1500,"Metaウェビナー")=0,"",SUMIFS(日次入力!$D$4:$D$1500,日次入力!$A$4:$A$1500,">="&DATE(2026,8,18),日次入力!$A$4:$A$1500,"<="&DATE(2026,8,24),日次入力!$C$4:$C$1500,"Metaウェビナー")) | D25: =IF(COUNTIFS(日次入力!$A$4:$A$1500,">="&DATE(2026,8,18),日次入力!$A$4:$A$1500,"<="&DATE(2026,8,24),日次入力!$C$4:$C$1500,"Metaウェビナー")=0,"",SUMIFS(日次入力!$E$4:$E$1500,日次入力!$A$4:$A$1500,">="&DATE(2026,8,18),日次入力!$A$4:$A$1500,"<="&DATE(2026,8,24),日次入力!$C$4:$C$1500,"Metaウェビナー")) | E25: =IF(COUNTIFS(日次入力!$A$4:$A$1500,">="&DATE(2026,8,18),日次入力!$A$4:$A$1500,"<="&DATE(2026,8,24),日次入力!$C$4:$C$1500,"Metaウェビナー")=0,"",SUMIFS(日次入力!$F$4:$F$1500,日次入力!$A$4:$A$1500,">="&DATE(2026,8,18),日次入力!$A$4:$A$1500,"<="&DATE(2026,8,24),日次入力!$C$4:$C$1500,"Metaウェビナー")) | F25: =IF(COUNTIFS(日次入力!$A$4:$A$1500,">="&DATE(2026,8,18),日次入力!$A$4:$A$1500,"<="&DATE(2026,8,24),日次入力!$C$4:$C$1500,"Metaウェビナー")=0,"",SUMIFS(日次入力!$G$4:$G$1500,日次入力!$A$4:$A$1500,">="&DATE(2026,8,18),日次入力!$A$4:$A$1500,"<="&DATE(2026,8,24),日次入力!$C$4:$C$1500,"Metaウェビナー")) | G25: =IFERROR(E25/D25,"") | H25: =IFERROR(C25/E25,"") | I25: =IFERROR(C25/D25*1000,"") | J25: =IFERROR(F25/E25,"") | K25: =IFERROR(C25/F25,"") | L25: =IF(COUNTIFS(日次入力!$A$4:$A$1500,">="&DATE(2026,8,18),日次入力!$A$4:$A$1500,"<="&DATE(2026,8,24),日次入力!$C$4:$C$1500,"Metaウェビナー")=0,"",SUMIFS(日次入力!$H$4:$H$1500,日次入力!$A$4:$A$1500,">="&DATE(2026,8,18),日次入力!$A$4:$A$1500,"<="&DATE(2026,8,24),日次入力!$C$4:$C$1500,"Metaウェビナー")) | M25: =IF(L25="","",IFERROR(L25/F25,"")) | N25: =IF(COUNTIFS(日次入力!$A$4:$A$1500,">="&DATE(2026,8,18),日次入力!$A$4:$A$1500,"<="&DATE(2026,8,24),日次入力!$C$4:$C$1500,"Metaウェビナー")=0,"",SUMIFS(日次入力!$I$4:$I$1500,日次入力!$A$4:$A$1500,">="&DATE(2026,8,18),日次入力!$A$4:$A$1500,"<="&DATE(2026,8,24),日次入力!$C$4:$C$1500,"Metaウェビナー")) | O25: =IF(N25="","",IFERROR(N25/L25,"")) | P25: =IF(N25=0,"",IFERROR(C25/N25,"")) | Q25: =IF(N25=0,"",IFERROR(IF(C25/N25<=用語集!$B$22,"◎ 許容内","✗ 超過"),"—")) -> — | R25: =IFERROR(用語集!$B$22/P25,"")
A26: W21 | B26: 8/25–8/31 | C26: =IF(COUNTIFS(日次入力!$A$4:$A$1500,">="&DATE(2026,8,25),日次入力!$A$4:$A$1500,"<="&DATE(2026,8,31),日次入力!$C$4:$C$1500,"Metaウェビナー")=0,"",SUMIFS(日次入力!$D$4:$D$1500,日次入力!$A$4:$A$1500,">="&DATE(2026,8,25),日次入力!$A$4:$A$1500,"<="&DATE(2026,8,31),日次入力!$C$4:$C$1500,"Metaウェビナー")) | D26: =IF(COUNTIFS(日次入力!$A$4:$A$1500,">="&DATE(2026,8,25),日次入力!$A$4:$A$1500,"<="&DATE(2026,8,31),日次入力!$C$4:$C$1500,"Metaウェビナー")=0,"",SUMIFS(日次入力!$E$4:$E$1500,日次入力!$A$4:$A$1500,">="&DATE(2026,8,25),日次入力!$A$4:$A$1500,"<="&DATE(2026,8,31),日次入力!$C$4:$C$1500,"Metaウェビナー")) | E26: =IF(COUNTIFS(日次入力!$A$4:$A$1500,">="&DATE(2026,8,25),日次入力!$A$4:$A$1500,"<="&DATE(2026,8,31),日次入力!$C$4:$C$1500,"Metaウェビナー")=0,"",SUMIFS(日次入力!$F$4:$F$1500,日次入力!$A$4:$A$1500,">="&DATE(2026,8,25),日次入力!$A$4:$A$1500,"<="&DATE(2026,8,31),日次入力!$C$4:$C$1500,"Metaウェビナー")) | F26: =IF(COUNTIFS(日次入力!$A$4:$A$1500,">="&DATE(2026,8,25),日次入力!$A$4:$A$1500,"<="&DATE(2026,8,31),日次入力!$C$4:$C$1500,"Metaウェビナー")=0,"",SUMIFS(日次入力!$G$4:$G$1500,日次入力!$A$4:$A$1500,">="&DATE(2026,8,25),日次入力!$A$4:$A$1500,"<="&DATE(2026,8,31),日次入力!$C$4:$C$1500,"Metaウェビナー")) | G26: =IFERROR(E26/D26,"") | H26: =IFERROR(C26/E26,"") | I26: =IFERROR(C26/D26*1000,"") | J26: =IFERROR(F26/E26,"") | K26: =IFERROR(C26/F26,"") | L26: =IF(COUNTIFS(日次入力!$A$4:$A$1500,">="&DATE(2026,8,25),日次入力!$A$4:$A$1500,"<="&DATE(2026,8,31),日次入力!$C$4:$C$1500,"Metaウェビナー")=0,"",SUMIFS(日次入力!$H$4:$H$1500,日次入力!$A$4:$A$1500,">="&DATE(2026,8,25),日次入力!$A$4:$A$1500,"<="&DATE(2026,8,31),日次入力!$C$4:$C$1500,"Metaウェビナー")) | M26: =IF(L26="","",IFERROR(L26/F26,"")) | N26: =IF(COUNTIFS(日次入力!$A$4:$A$1500,">="&DATE(2026,8,25),日次入力!$A$4:$A$1500,"<="&DATE(2026,8,31),日次入力!$C$4:$C$1500,"Metaウェビナー")=0,"",SUMIFS(日次入力!$I$4:$I$1500,日次入力!$A$4:$A$1500,">="&DATE(2026,8,25),日次入力!$A$4:$A$1500,"<="&DATE(2026,8,31),日次入力!$C$4:$C$1500,"Metaウェビナー")) | O26: =IF(N26="","",IFERROR(N26/L26,"")) | P26: =IF(N26=0,"",IFERROR(C26/N26,"")) | Q26: =IF(N26=0,"",IFERROR(IF(C26/N26<=用語集!$B$22,"◎ 許容内","✗ 超過"),"—")) -> — | R26: =IFERROR(用語集!$B$22/P26,"")
A27: W22 | B27: 9/1–9/7 | C27: =IF(COUNTIFS(日次入力!$A$4:$A$1500,">="&DATE(2026,9,1),日次入力!$A$4:$A$1500,"<="&DATE(2026,9,7),日次入力!$C$4:$C$1500,"Metaウェビナー")=0,"",SUMIFS(日次入力!$D$4:$D$1500,日次入力!$A$4:$A$1500,">="&DATE(2026,9,1),日次入力!$A$4:$A$1500,"<="&DATE(2026,9,7),日次入力!$C$4:$C$1500,"Metaウェビナー")) | D27: =IF(COUNTIFS(日次入力!$A$4:$A$1500,">="&DATE(2026,9,1),日次入力!$A$4:$A$1500,"<="&DATE(2026,9,7),日次入力!$C$4:$C$1500,"Metaウェビナー")=0,"",SUMIFS(日次入力!$E$4:$E$1500,日次入力!$A$4:$A$1500,">="&DATE(2026,9,1),日次入力!$A$4:$A$1500,"<="&DATE(2026,9,7),日次入力!$C$4:$C$1500,"Metaウェビナー")) | E27: =IF(COUNTIFS(日次入力!$A$4:$A$1500,">="&DATE(2026,9,1),日次入力!$A$4:$A$1500,"<="&DATE(2026,9,7),日次入力!$C$4:$C$1500,"Metaウェビナー")=0,"",SUMIFS(日次入力!$F$4:$F$1500,日次入力!$A$4:$A$1500,">="&DATE(2026,9,1),日次入力!$A$4:$A$1500,"<="&DATE(2026,9,7),日次入力!$C$4:$C$1500,"Metaウェビナー")) | F27: =IF(COUNTIFS(日次入力!$A$4:$A$1500,">="&DATE(2026,9,1),日次入力!$A$4:$A$1500,"<="&DATE(2026,9,7),日次入力!$C$4:$C$1500,"Metaウェビナー")=0,"",SUMIFS(日次入力!$G$4:$G$1500,日次入力!$A$4:$A$1500,">="&DATE(2026,9,1),日次入力!$A$4:$A$1500,"<="&DATE(2026,9,7),日次入力!$C$4:$C$1500,"Metaウェビナー")) | G27: =IFERROR(E27/D27,"") | H27: =IFERROR(C27/E27,"") | I27: =IFERROR(C27/D27*1000,"") | J27: =IFERROR(F27/E27,"") | K27: =IFERROR(C27/F27,"") | L27: =IF(COUNTIFS(日次入力!$A$4:$A$1500,">="&DATE(2026,9,1),日次入力!$A$4:$A$1500,"<="&DATE(2026,9,7),日次入力!$C$4:$C$1500,"Metaウェビナー")=0,"",SUMIFS(日次入力!$H$4:$H$1500,日次入力!$A$4:$A$1500,">="&DATE(2026,9,1),日次入力!$A$4:$A$1500,"<="&DATE(2026,9,7),日次入力!$C$4:$C$1500,"Metaウェビナー")) | M27: =IF(L27="","",IFERROR(L27/F27,"")) | N27: =IF(COUNTIFS(日次入力!$A$4:$A$1500,">="&DATE(2026,9,1),日次入力!$A$4:$A$1500,"<="&DATE(2026,9,7),日次入力!$C$4:$C$1500,"Metaウェビナー")=0,"",SUMIFS(日次入力!$I$4:$I$1500,日次入力!$A$4:$A$1500,">="&DATE(2026,9,1),日次入力!$A$4:$A$1500,"<="&DATE(2026,9,7),日次入力!$C$4:$C$1500,"Metaウェビナー")) | O27: =IF(N27="","",IFERROR(N27/L27,"")) | P27: =IF(N27=0,"",IFERROR(C27/N27,"")) | Q27: =IF(N27=0,"",IFERROR(IF(C27/N27<=用語集!$B$22,"◎ 許容内","✗ 超過"),"—")) -> — | R27: =IFERROR(用語集!$B$22/P27,"")
A28: W23 | B28: 9/8–9/14 | C28: =IF(COUNTIFS(日次入力!$A$4:$A$1500,">="&DATE(2026,9,8),日次入力!$A$4:$A$1500,"<="&DATE(2026,9,14),日次入力!$C$4:$C$1500,"Metaウェビナー")=0,"",SUMIFS(日次入力!$D$4:$D$1500,日次入力!$A$4:$A$1500,">="&DATE(2026,9,8),日次入力!$A$4:$A$1500,"<="&DATE(2026,9,14),日次入力!$C$4:$C$1500,"Metaウェビナー")) | D28: =IF(COUNTIFS(日次入力!$A$4:$A$1500,">="&DATE(2026,9,8),日次入力!$A$4:$A$1500,"<="&DATE(2026,9,14),日次入力!$C$4:$C$1500,"Metaウェビナー")=0,"",SUMIFS(日次入力!$E$4:$E$1500,日次入力!$A$4:$A$1500,">="&DATE(2026,9,8),日次入力!$A$4:$A$1500,"<="&DATE(2026,9,14),日次入力!$C$4:$C$1500,"Metaウェビナー")) | E28: =IF(COUNTIFS(日次入力!$A$4:$A$1500,">="&DATE(2026,9,8),日次入力!$A$4:$A$1500,"<="&DATE(2026,9,14),日次入力!$C$4:$C$1500,"Metaウェビナー")=0,"",SUMIFS(日次入力!$F$4:$F$1500,日次入力!$A$4:$A$1500,">="&DATE(2026,9,8),日次入力!$A$4:$A$1500,"<="&DATE(2026,9,14),日次入力!$C$4:$C$1500,"Metaウェビナー")) | F28: =IF(COUNTIFS(日次入力!$A$4:$A$1500,">="&DATE(2026,9,8),日次入力!$A$4:$A$1500,"<="&DATE(2026,9,14),日次入力!$C$4:$C$1500,"Metaウェビナー")=0,"",SUMIFS(日次入力!$G$4:$G$1500,日次入力!$A$4:$A$1500,">="&DATE(2026,9,8),日次入力!$A$4:$A$1500,"<="&DATE(2026,9,14),日次入力!$C$4:$C$1500,"Metaウェビナー")) | G28: =IFERROR(E28/D28,"") | H28: =IFERROR(C28/E28,"") | I28: =IFERROR(C28/D28*1000,"") | J28: =IFERROR(F28/E28,"") | K28: =IFERROR(C28/F28,"") | L28: =IF(COUNTIFS(日次入力!$A$4:$A$1500,">="&DATE(2026,9,8),日次入力!$A$4:$A$1500,"<="&DATE(2026,9,14),日次入力!$C$4:$C$1500,"Metaウェビナー")=0,"",SUMIFS(日次入力!$H$4:$H$1500,日次入力!$A$4:$A$1500,">="&DATE(2026,9,8),日次入力!$A$4:$A$1500,"<="&DATE(2026,9,14),日次入力!$C$4:$C$1500,"Metaウェビナー")) | M28: =IF(L28="","",IFERROR(L28/F28,"")) | N28: =IF(COUNTIFS(日次入力!$A$4:$A$1500,">="&DATE(2026,9,8),日次入力!$A$4:$A$1500,"<="&DATE(2026,9,14),日次入力!$C$4:$C$1500,"Metaウェビナー")=0,"",SUMIFS(日次入力!$I$4:$I$1500,日次入力!$A$4:$A$1500,">="&DATE(2026,9,8),日次入力!$A$4:$A$1500,"<="&DATE(2026,9,14),日次入力!$C$4:$C$1500,"Metaウェビナー")) | O28: =IF(N28="","",IFERROR(N28/L28,"")) | P28: =IF(N28=0,"",IFERROR(C28/N28,"")) | Q28: =IF(N28=0,"",IFERROR(IF(C28/N28<=用語集!$B$22,"◎ 許容内","✗ 超過"),"—")) -> — | R28: =IFERROR(用語集!$B$22/P28,"")
A29: W24 | B29: 9/15–9/21 | C29: =IF(COUNTIFS(日次入力!$A$4:$A$1500,">="&DATE(2026,9,15),日次入力!$A$4:$A$1500,"<="&DATE(2026,9,21),日次入力!$C$4:$C$1500,"Metaウェビナー")=0,"",SUMIFS(日次入力!$D$4:$D$1500,日次入力!$A$4:$A$1500,">="&DATE(2026,9,15),日次入力!$A$4:$A$1500,"<="&DATE(2026,9,21),日次入力!$C$4:$C$1500,"Metaウェビナー")) | D29: =IF(COUNTIFS(日次入力!$A$4:$A$1500,">="&DATE(2026,9,15),日次入力!$A$4:$A$1500,"<="&DATE(2026,9,21),日次入力!$C$4:$C$1500,"Metaウェビナー")=0,"",SUMIFS(日次入力!$E$4:$E$1500,日次入力!$A$4:$A$1500,">="&DATE(2026,9,15),日次入力!$A$4:$A$1500,"<="&DATE(2026,9,21),日次入力!$C$4:$C$1500,"Metaウェビナー")) | E29: =IF(COUNTIFS(日次入力!$A$4:$A$1500,">="&DATE(2026,9,15),日次入力!$A$4:$A$1500,"<="&DATE(2026,9,21),日次入力!$C$4:$C$1500,"Metaウェビナー")=0,"",SUMIFS(日次入力!$F$4:$F$1500,日次入力!$A$4:$A$1500,">="&DATE(2026,9,15),日次入力!$A$4:$A$1500,"<="&DATE(2026,9,21),日次入力!$C$4:$C$1500,"Metaウェビナー")) | F29: =IF(COUNTIFS(日次入力!$A$4:$A$1500,">="&DATE(2026,9,15),日次入力!$A$4:$A$1500,"<="&DATE(2026,9,21),日次入力!$C$4:$C$1500,"Metaウェビナー")=0,"",SUMIFS(日次入力!$G$4:$G$1500,日次入力!$A$4:$A$1500,">="&DATE(2026,9,15),日次入力!$A$4:$A$1500,"<="&DATE(2026,9,21),日次入力!$C$4:$C$1500,"Metaウェビナー")) | G29: =IFERROR(E29/D29,"") | H29: =IFERROR(C29/E29,"") | I29: =IFERROR(C29/D29*1000,"") | J29: =IFERROR(F29/E29,"") | K29: =IFERROR(C29/F29,"") | L29: =IF(COUNTIFS(日次入力!$A$4:$A$1500,">="&DATE(2026,9,15),日次入力!$A$4:$A$1500,"<="&DATE(2026,9,21),日次入力!$C$4:$C$1500,"Metaウェビナー")=0,"",SUMIFS(日次入力!$H$4:$H$1500,日次入力!$A$4:$A$1500,">="&DATE(2026,9,15),日次入力!$A$4:$A$1500,"<="&DATE(2026,9,21),日次入力!$C$4:$C$1500,"Metaウェビナー")) | M29: =IF(L29="","",IFERROR(L29/F29,"")) | N29: =IF(COUNTIFS(日次入力!$A$4:$A$1500,">="&DATE(2026,9,15),日次入力!$A$4:$A$1500,"<="&DATE(2026,9,21),日次入力!$C$4:$C$1500,"Metaウェビナー")=0,"",SUMIFS(日次入力!$I$4:$I$1500,日次入力!$A$4:$A$1500,">="&DATE(2026,9,15),日次入力!$A$4:$A$1500,"<="&DATE(2026,9,21),日次入力!$C$4:$C$1500,"Metaウェビナー")) | O29: =IF(N29="","",IFERROR(N29/L29,"")) | P29: =IF(N29=0,"",IFERROR(C29/N29,"")) | Q29: =IF(N29=0,"",IFERROR(IF(C29/N29<=用語集!$B$22,"◎ 許容内","✗ 超過"),"—")) -> — | R29: =IFERROR(用語集!$B$22/P29,"")
A30: W25 | B30: 9/22–9/28 | C30: =IF(COUNTIFS(日次入力!$A$4:$A$1500,">="&DATE(2026,9,22),日次入力!$A$4:$A$1500,"<="&DATE(2026,9,28),日次入力!$C$4:$C$1500,"Metaウェビナー")=0,"",SUMIFS(日次入力!$D$4:$D$1500,日次入力!$A$4:$A$1500,">="&DATE(2026,9,22),日次入力!$A$4:$A$1500,"<="&DATE(2026,9,28),日次入力!$C$4:$C$1500,"Metaウェビナー")) | D30: =IF(COUNTIFS(日次入力!$A$4:$A$1500,">="&DATE(2026,9,22),日次入力!$A$4:$A$1500,"<="&DATE(2026,9,28),日次入力!$C$4:$C$1500,"Metaウェビナー")=0,"",SUMIFS(日次入力!$E$4:$E$1500,日次入力!$A$4:$A$1500,">="&DATE(2026,9,22),日次入力!$A$4:$A$1500,"<="&DATE(2026,9,28),日次入力!$C$4:$C$1500,"Metaウェビナー")) | E30: =IF(COUNTIFS(日次入力!$A$4:$A$1500,">="&DATE(2026,9,22),日次入力!$A$4:$A$1500,"<="&DATE(2026,9,28),日次入力!$C$4:$C$1500,"Metaウェビナー")=0,"",SUMIFS(日次入力!$F$4:$F$1500,日次入力!$A$4:$A$1500,">="&DATE(2026,9,22),日次入力!$A$4:$A$1500,"<="&DATE(2026,9,28),日次入力!$C$4:$C$1500,"Metaウェビナー")) | F30: =IF(COUNTIFS(日次入力!$A$4:$A$1500,">="&DATE(2026,9,22),日次入力!$A$4:$A$1500,"<="&DATE(2026,9,28),日次入力!$C$4:$C$1500,"Metaウェビナー")=0,"",SUMIFS(日次入力!$G$4:$G$1500,日次入力!$A$4:$A$1500,">="&DATE(2026,9,22),日次入力!$A$4:$A$1500,"<="&DATE(2026,9,28),日次入力!$C$4:$C$1500,"Metaウェビナー")) | G30: =IFERROR(E30/D30,"") | H30: =IFERROR(C30/E30,"") | I30: =IFERROR(C30/D30*1000,"") | J30: =IFERROR(F30/E30,"") | K30: =IFERROR(C30/F30,"") | L30: =IF(COUNTIFS(日次入力!$A$4:$A$1500,">="&DATE(2026,9,22),日次入力!$A$4:$A$1500,"<="&DATE(2026,9,28),日次入力!$C$4:$C$1500,"Metaウェビナー")=0,"",SUMIFS(日次入力!$H$4:$H$1500,日次入力!$A$4:$A$1500,">="&DATE(2026,9,22),日次入力!$A$4:$A$1500,"<="&DATE(2026,9,28),日次入力!$C$4:$C$1500,"Metaウェビナー")) | M30: =IF(L30="","",IFERROR(L30/F30,"")) | N30: =IF(COUNTIFS(日次入力!$A$4:$A$1500,">="&DATE(2026,9,22),日次入力!$A$4:$A$1500,"<="&DATE(2026,9,28),日次入力!$C$4:$C$1500,"Metaウェビナー")=0,"",SUMIFS(日次入力!$I$4:$I$1500,日次入力!$A$4:$A$1500,">="&DATE(2026,9,22),日次入力!$A$4:$A$1500,"<="&DATE(2026,9,28),日次入力!$C$4:$C$1500,"Metaウェビナー")) | O30: =IF(N30="","",IFERROR(N30/L30,"")) | P30: =IF(N30=0,"",IFERROR(C30/N30,"")) | Q30: =IF(N30=0,"",IFERROR(IF(C30/N30<=用語集!$B$22,"◎ 許容内","✗ 超過"),"—")) -> — | R30: =IFERROR(用語集!$B$22/P30,"")
A31: W26 | B31: 9/29–10/5 | C31: =IF(COUNTIFS(日次入力!$A$4:$A$1500,">="&DATE(2026,9,29),日次入力!$A$4:$A$1500,"<="&DATE(2026,10,5),日次入力!$C$4:$C$1500,"Metaウェビナー")=0,"",SUMIFS(日次入力!$D$4:$D$1500,日次入力!$A$4:$A$1500,">="&DATE(2026,9,29),日次入力!$A$4:$A$1500,"<="&DATE(2026,10,5),日次入力!$C$4:$C$1500,"Metaウェビナー")) | D31: =IF(COUNTIFS(日次入力!$A$4:$A$1500,">="&DATE(2026,9,29),日次入力!$A$4:$A$1500,"<="&DATE(2026,10,5),日次入力!$C$4:$C$1500,"Metaウェビナー")=0,"",SUMIFS(日次入力!$E$4:$E$1500,日次入力!$A$4:$A$1500,">="&DATE(2026,9,29),日次入力!$A$4:$A$1500,"<="&DATE(2026,10,5),日次入力!$C$4:$C$1500,"Metaウェビナー")) | E31: =IF(COUNTIFS(日次入力!$A$4:$A$1500,">="&DATE(2026,9,29),日次入力!$A$4:$A$1500,"<="&DATE(2026,10,5),日次入力!$C$4:$C$1500,"Metaウェビナー")=0,"",SUMIFS(日次入力!$F$4:$F$1500,日次入力!$A$4:$A$1500,">="&DATE(2026,9,29),日次入力!$A$4:$A$1500,"<="&DATE(2026,10,5),日次入力!$C$4:$C$1500,"Metaウェビナー")) | F31: =IF(COUNTIFS(日次入力!$A$4:$A$1500,">="&DATE(2026,9,29),日次入力!$A$4:$A$1500,"<="&DATE(2026,10,5),日次入力!$C$4:$C$1500,"Metaウェビナー")=0,"",SUMIFS(日次入力!$G$4:$G$1500,日次入力!$A$4:$A$1500,">="&DATE(2026,9,29),日次入力!$A$4:$A$1500,"<="&DATE(2026,10,5),日次入力!$C$4:$C$1500,"Metaウェビナー")) | G31: =IFERROR(E31/D31,"") | H31: =IFERROR(C31/E31,"") | I31: =IFERROR(C31/D31*1000,"") | J31: =IFERROR(F31/E31,"") | K31: =IFERROR(C31/F31,"") | L31: =IF(COUNTIFS(日次入力!$A$4:$A$1500,">="&DATE(2026,9,29),日次入力!$A$4:$A$1500,"<="&DATE(2026,10,5),日次入力!$C$4:$C$1500,"Metaウェビナー")=0,"",SUMIFS(日次入力!$H$4:$H$1500,日次入力!$A$4:$A$1500,">="&DATE(2026,9,29),日次入力!$A$4:$A$1500,"<="&DATE(2026,10,5),日次入力!$C$4:$C$1500,"Metaウェビナー")) | M31: =IF(L31="","",IFERROR(L31/F31,"")) | N31: =IF(COUNTIFS(日次入力!$A$4:$A$1500,">="&DATE(2026,9,29),日次入力!$A$4:$A$1500,"<="&DATE(2026,10,5),日次入力!$C$4:$C$1500,"Metaウェビナー")=0,"",SUMIFS(日次入力!$I$4:$I$1500,日次入力!$A$4:$A$1500,">="&DATE(2026,9,29),日次入力!$A$4:$A$1500,"<="&DATE(2026,10,5),日次入力!$C$4:$C$1500,"Metaウェビナー")) | O31: =IF(N31="","",IFERROR(N31/L31,"")) | P31: =IF(N31=0,"",IFERROR(C31/N31,"")) | Q31: =IF(N31=0,"",IFERROR(IF(C31/N31<=用語集!$B$22,"◎ 許容内","✗ 超過"),"—")) -> — | R31: =IFERROR(用語集!$B$22/P31,"")
A32: W27 | B32: 10/6–10/12 | C32: =IF(COUNTIFS(日次入力!$A$4:$A$1500,">="&DATE(2026,10,6),日次入力!$A$4:$A$1500,"<="&DATE(2026,10,12),日次入力!$C$4:$C$1500,"Metaウェビナー")=0,"",SUMIFS(日次入力!$D$4:$D$1500,日次入力!$A$4:$A$1500,">="&DATE(2026,10,6),日次入力!$A$4:$A$1500,"<="&DATE(2026,10,12),日次入力!$C$4:$C$1500,"Metaウェビナー")) | D32: =IF(COUNTIFS(日次入力!$A$4:$A$1500,">="&DATE(2026,10,6),日次入力!$A$4:$A$1500,"<="&DATE(2026,10,12),日次入力!$C$4:$C$1500,"Metaウェビナー")=0,"",SUMIFS(日次入力!$E$4:$E$1500,日次入力!$A$4:$A$1500,">="&DATE(2026,10,6),日次入力!$A$4:$A$1500,"<="&DATE(2026,10,12),日次入力!$C$4:$C$1500,"Metaウェビナー")) | E32: =IF(COUNTIFS(日次入力!$A$4:$A$1500,">="&DATE(2026,10,6),日次入力!$A$4:$A$1500,"<="&DATE(2026,10,12),日次入力!$C$4:$C$1500,"Metaウェビナー")=0,"",SUMIFS(日次入力!$F$4:$F$1500,日次入力!$A$4:$A$1500,">="&DATE(2026,10,6),日次入力!$A$4:$A$1500,"<="&DATE(2026,10,12),日次入力!$C$4:$C$1500,"Metaウェビナー")) | F32: =IF(COUNTIFS(日次入力!$A$4:$A$1500,">="&DATE(2026,10,6),日次入力!$A$4:$A$1500,"<="&DATE(2026,10,12),日次入力!$C$4:$C$1500,"Metaウェビナー")=0,"",SUMIFS(日次入力!$G$4:$G$1500,日次入力!$A$4:$A$1500,">="&DATE(2026,10,6),日次入力!$A$4:$A$1500,"<="&DATE(2026,10,12),日次入力!$C$4:$C$1500,"Metaウェビナー")) | G32: =IFERROR(E32/D32,"") | H32: =IFERROR(C32/E32,"") | I32: =IFERROR(C32/D32*1000,"") | J32: =IFERROR(F32/E32,"") | K32: =IFERROR(C32/F32,"") | L32: =IF(COUNTIFS(日次入力!$A$4:$A$1500,">="&DATE(2026,10,6),日次入力!$A$4:$A$1500,"<="&DATE(2026,10,12),日次入力!$C$4:$C$1500,"Metaウェビナー")=0,"",SUMIFS(日次入力!$H$4:$H$1500,日次入力!$A$4:$A$1500,">="&DATE(2026,10,6),日次入力!$A$4:$A$1500,"<="&DATE(2026,10,12),日次入力!$C$4:$C$1500,"Metaウェビナー")) | M32: =IF(L32="","",IFERROR(L32/F32,"")) | N32: =IF(COUNTIFS(日次入力!$A$4:$A$1500,">="&DATE(2026,10,6),日次入力!$A$4:$A$1500,"<="&DATE(2026,10,12),日次入力!$C$4:$C$1500,"Metaウェビナー")=0,"",SUMIFS(日次入力!$I$4:$I$1500,日次入力!$A$4:$A$1500,">="&DATE(2026,10,6),日次入力!$A$4:$A$1500,"<="&DATE(2026,10,12),日次入力!$C$4:$C$1500,"Metaウェビナー")) | O32: =IF(N32="","",IFERROR(N32/L32,"")) | P32: =IF(N32=0,"",IFERROR(C32/N32,"")) | Q32: =IF(N32=0,"",IFERROR(IF(C32/N32<=用語集!$B$22,"◎ 許容内","✗ 超過"),"—")) -> — | R32: =IFERROR(用語集!$B$22/P32,"")
A33: W28 | B33: 10/13–10/19 | C33: =IF(COUNTIFS(日次入力!$A$4:$A$1500,">="&DATE(2026,10,13),日次入力!$A$4:$A$1500,"<="&DATE(2026,10,19),日次入力!$C$4:$C$1500,"Metaウェビナー")=0,"",SUMIFS(日次入力!$D$4:$D$1500,日次入力!$A$4:$A$1500,">="&DATE(2026,10,13),日次入力!$A$4:$A$1500,"<="&DATE(2026,10,19),日次入力!$C$4:$C$1500,"Metaウェビナー")) | D33: =IF(COUNTIFS(日次入力!$A$4:$A$1500,">="&DATE(2026,10,13),日次入力!$A$4:$A$1500,"<="&DATE(2026,10,19),日次入力!$C$4:$C$1500,"Metaウェビナー")=0,"",SUMIFS(日次入力!$E$4:$E$1500,日次入力!$A$4:$A$1500,">="&DATE(2026,10,13),日次入力!$A$4:$A$1500,"<="&DATE(2026,10,19),日次入力!$C$4:$C$1500,"Metaウェビナー")) | E33: =IF(COUNTIFS(日次入力!$A$4:$A$1500,">="&DATE(2026,10,13),日次入力!$A$4:$A$1500,"<="&DATE(2026,10,19),日次入力!$C$4:$C$1500,"Metaウェビナー")=0,"",SUMIFS(日次入力!$F$4:$F$1500,日次入力!$A$4:$A$1500,">="&DATE(2026,10,13),日次入力!$A$4:$A$1500,"<="&DATE(2026,10,19),日次入力!$C$4:$C$1500,"Metaウェビナー")) | F33: =IF(COUNTIFS(日次入力!$A$4:$A$1500,">="&DATE(2026,10,13),日次入力!$A$4:$A$1500,"<="&DATE(2026,10,19),日次入力!$C$4:$C$1500,"Metaウェビナー")=0,"",SUMIFS(日次入力!$G$4:$G$1500,日次入力!$A$4:$A$1500,">="&DATE(2026,10,13),日次入力!$A$4:$A$1500,"<="&DATE(2026,10,19),日次入力!$C$4:$C$1500,"Metaウェビナー")) | G33: =IFERROR(E33/D33,"") | H33: =IFERROR(C33/E33,"") | I33: =IFERROR(C33/D33*1000,"") | J33: =IFERROR(F33/E33,"") | K33: =IFERROR(C33/F33,"") | L33: =IF(COUNTIFS(日次入力!$A$4:$A$1500,">="&DATE(2026,10,13),日次入力!$A$4:$A$1500,"<="&DATE(2026,10,19),日次入力!$C$4:$C$1500,"Metaウェビナー")=0,"",SUMIFS(日次入力!$H$4:$H$1500,日次入力!$A$4:$A$1500,">="&DATE(2026,10,13),日次入力!$A$4:$A$1500,"<="&DATE(2026,10,19),日次入力!$C$4:$C$1500,"Metaウェビナー")) | M33: =IF(L33="","",IFERROR(L33/F33,"")) | N33: =IF(COUNTIFS(日次入力!$A$4:$A$1500,">="&DATE(2026,10,13),日次入力!$A$4:$A$1500,"<="&DATE(2026,10,19),日次入力!$C$4:$C$1500,"Metaウェビナー")=0,"",SUMIFS(日次入力!$I$4:$I$1500,日次入力!$A$4:$A$1500,">="&DATE(2026,10,13),日次入力!$A$4:$A$1500,"<="&DATE(2026,10,19),日次入力!$C$4:$C$1500,"Metaウェビナー")) | O33: =IF(N33="","",IFERROR(N33/L33,"")) | P33: =IF(N33=0,"",IFERROR(C33/N33,"")) | Q33: =IF(N33=0,"",IFERROR(IF(C33/N33<=用語集!$B$22,"◎ 許容内","✗ 超過"),"—")) -> — | R33: =IFERROR(用語集!$B$22/P33,"")
A34: W29 | B34: 10/20–10/26 | C34: =IF(COUNTIFS(日次入力!$A$4:$A$1500,">="&DATE(2026,10,20),日次入力!$A$4:$A$1500,"<="&DATE(2026,10,26),日次入力!$C$4:$C$1500,"Metaウェビナー")=0,"",SUMIFS(日次入力!$D$4:$D$1500,日次入力!$A$4:$A$1500,">="&DATE(2026,10,20),日次入力!$A$4:$A$1500,"<="&DATE(2026,10,26),日次入力!$C$4:$C$1500,"Metaウェビナー")) | D34: =IF(COUNTIFS(日次入力!$A$4:$A$1500,">="&DATE(2026,10,20),日次入力!$A$4:$A$1500,"<="&DATE(2026,10,26),日次入力!$C$4:$C$1500,"Metaウェビナー")=0,"",SUMIFS(日次入力!$E$4:$E$1500,日次入力!$A$4:$A$1500,">="&DATE(2026,10,20),日次入力!$A$4:$A$1500,"<="&DATE(2026,10,26),日次入力!$C$4:$C$1500,"Metaウェビナー")) | E34: =IF(COUNTIFS(日次入力!$A$4:$A$1500,">="&DATE(2026,10,20),日次入力!$A$4:$A$1500,"<="&DATE(2026,10,26),日次入力!$C$4:$C$1500,"Metaウェビナー")=0,"",SUMIFS(日次入力!$F$4:$F$1500,日次入力!$A$4:$A$1500,">="&DATE(2026,10,20),日次入力!$A$4:$A$1500,"<="&DATE(2026,10,26),日次入力!$C$4:$C$1500,"Metaウェビナー")) | F34: =IF(COUNTIFS(日次入力!$A$4:$A$1500,">="&DATE(2026,10,20),日次入力!$A$4:$A$1500,"<="&DATE(2026,10,26),日次入力!$C$4:$C$1500,"Metaウェビナー")=0,"",SUMIFS(日次入力!$G$4:$G$1500,日次入力!$A$4:$A$1500,">="&DATE(2026,10,20),日次入力!$A$4:$A$1500,"<="&DATE(2026,10,26),日次入力!$C$4:$C$1500,"Metaウェビナー")) | G34: =IFERROR(E34/D34,"") | H34: =IFERROR(C34/E34,"") | I34: =IFERROR(C34/D34*1000,"") | J34: =IFERROR(F34/E34,"") | K34: =IFERROR(C34/F34,"") | L34: =IF(COUNTIFS(日次入力!$A$4:$A$1500,">="&DATE(2026,10,20),日次入力!$A$4:$A$1500,"<="&DATE(2026,10,26),日次入力!$C$4:$C$1500,"Metaウェビナー")=0,"",SUMIFS(日次入力!$H$4:$H$1500,日次入力!$A$4:$A$1500,">="&DATE(2026,10,20),日次入力!$A$4:$A$1500,"<="&DATE(2026,10,26),日次入力!$C$4:$C$1500,"Metaウェビナー")) | M34: =IF(L34="","",IFERROR(L34/F34,"")) | N34: =IF(COUNTIFS(日次入力!$A$4:$A$1500,">="&DATE(2026,10,20),日次入力!$A$4:$A$1500,"<="&DATE(2026,10,26),日次入力!$C$4:$C$1500,"Metaウェビナー")=0,"",SUMIFS(日次入力!$I$4:$I$1500,日次入力!$A$4:$A$1500,">="&DATE(2026,10,20),日次入力!$A$4:$A$1500,"<="&DATE(2026,10,26),日次入力!$C$4:$C$1500,"Metaウェビナー")) | O34: =IF(N34="","",IFERROR(N34/L34,"")) | P34: =IF(N34=0,"",IFERROR(C34/N34,"")) | Q34: =IF(N34=0,"",IFERROR(IF(C34/N34<=用語集!$B$22,"◎ 許容内","✗ 超過"),"—")) -> — | R34: =IFERROR(用語集!$B$22/P34,"")
A35: W30 | B35: 10/27–11/2 | C35: =IF(COUNTIFS(日次入力!$A$4:$A$1500,">="&DATE(2026,10,27),日次入力!$A$4:$A$1500,"<="&DATE(2026,11,2),日次入力!$C$4:$C$1500,"Metaウェビナー")=0,"",SUMIFS(日次入力!$D$4:$D$1500,日次入力!$A$4:$A$1500,">="&DATE(2026,10,27),日次入力!$A$4:$A$1500,"<="&DATE(2026,11,2),日次入力!$C$4:$C$1500,"Metaウェビナー")) | D35: =IF(COUNTIFS(日次入力!$A$4:$A$1500,">="&DATE(2026,10,27),日次入力!$A$4:$A$1500,"<="&DATE(2026,11,2),日次入力!$C$4:$C$1500,"Metaウェビナー")=0,"",SUMIFS(日次入力!$E$4:$E$1500,日次入力!$A$4:$A$1500,">="&DATE(2026,10,27),日次入力!$A$4:$A$1500,"<="&DATE(2026,11,2),日次入力!$C$4:$C$1500,"Metaウェビナー")) | E35: =IF(COUNTIFS(日次入力!$A$4:$A$1500,">="&DATE(2026,10,27),日次入力!$A$4:$A$1500,"<="&DATE(2026,11,2),日次入力!$C$4:$C$1500,"Metaウェビナー")=0,"",SUMIFS(日次入力!$F$4:$F$1500,日次入力!$A$4:$A$1500,">="&DATE(2026,10,27),日次入力!$A$4:$A$1500,"<="&DATE(2026,11,2),日次入力!$C$4:$C$1500,"Metaウェビナー")) | F35: =IF(COUNTIFS(日次入力!$A$4:$A$1500,">="&DATE(2026,10,27),日次入力!$A$4:$A$1500,"<="&DATE(2026,11,2),日次入力!$C$4:$C$1500,"Metaウェビナー")=0,"",SUMIFS(日次入力!$G$4:$G$1500,日次入力!$A$4:$A$1500,">="&DATE(2026,10,27),日次入力!$A$4:$A$1500,"<="&DATE(2026,11,2),日次入力!$C$4:$C$1500,"Metaウェビナー")) | G35: =IFERROR(E35/D35,"") | H35: =IFERROR(C35/E35,"") | I35: =IFERROR(C35/D35*1000,"") | J35: =IFERROR(F35/E35,"") | K35: =IFERROR(C35/F35,"") | L35: =IF(COUNTIFS(日次入力!$A$4:$A$1500,">="&DATE(2026,10,27),日次入力!$A$4:$A$1500,"<="&DATE(2026,11,2),日次入力!$C$4:$C$1500,"Metaウェビナー")=0,"",SUMIFS(日次入力!$H$4:$H$1500,日次入力!$A$4:$A$1500,">="&DATE(2026,10,27),日次入力!$A$4:$A$1500,"<="&DATE(2026,11,2),日次入力!$C$4:$C$1500,"Metaウェビナー")) | M35: =IF(L35="","",IFERROR(L35/F35,"")) | N35: =IF(COUNTIFS(日次入力!$A$4:$A$1500,">="&DATE(2026,10,27),日次入力!$A$4:$A$1500,"<="&DATE(2026,11,2),日次入力!$C$4:$C$1500,"Metaウェビナー")=0,"",SUMIFS(日次入力!$I$4:$I$1500,日次入力!$A$4:$A$1500,">="&DATE(2026,10,27),日次入力!$A$4:$A$1500,"<="&DATE(2026,11,2),日次入力!$C$4:$C$1500,"Metaウェビナー")) | O35: =IF(N35="","",IFERROR(N35/L35,"")) | P35: =IF(N35=0,"",IFERROR(C35/N35,"")) | Q35: =IF(N35=0,"",IFERROR(IF(C35/N35<=用語集!$B$22,"◎ 許容内","✗ 超過"),"—")) -> — | R35: =IFERROR(用語集!$B$22/P35,"")
A36: W31 | B36: 11/3–11/9 | C36: =IF(COUNTIFS(日次入力!$A$4:$A$1500,">="&DATE(2026,11,3),日次入力!$A$4:$A$1500,"<="&DATE(2026,11,9),日次入力!$C$4:$C$1500,"Metaウェビナー")=0,"",SUMIFS(日次入力!$D$4:$D$1500,日次入力!$A$4:$A$1500,">="&DATE(2026,11,3),日次入力!$A$4:$A$1500,"<="&DATE(2026,11,9),日次入力!$C$4:$C$1500,"Metaウェビナー")) | D36: =IF(COUNTIFS(日次入力!$A$4:$A$1500,">="&DATE(2026,11,3),日次入力!$A$4:$A$1500,"<="&DATE(2026,11,9),日次入力!$C$4:$C$1500,"Metaウェビナー")=0,"",SUMIFS(日次入力!$E$4:$E$1500,日次入力!$A$4:$A$1500,">="&DATE(2026,11,3),日次入力!$A$4:$A$1500,"<="&DATE(2026,11,9),日次入力!$C$4:$C$1500,"Metaウェビナー")) | E36: =IF(COUNTIFS(日次入力!$A$4:$A$1500,">="&DATE(2026,11,3),日次入力!$A$4:$A$1500,"<="&DATE(2026,11,9),日次入力!$C$4:$C$1500,"Metaウェビナー")=0,"",SUMIFS(日次入力!$F$4:$F$1500,日次入力!$A$4:$A$1500,">="&DATE(2026,11,3),日次入力!$A$4:$A$1500,"<="&DATE(2026,11,9),日次入力!$C$4:$C$1500,"Metaウェビナー")) | F36: =IF(COUNTIFS(日次入力!$A$4:$A$1500,">="&DATE(2026,11,3),日次入力!$A$4:$A$1500,"<="&DATE(2026,11,9),日次入力!$C$4:$C$1500,"Metaウェビナー")=0,"",SUMIFS(日次入力!$G$4:$G$1500,日次入力!$A$4:$A$1500,">="&DATE(2026,11,3),日次入力!$A$4:$A$1500,"<="&DATE(2026,11,9),日次入力!$C$4:$C$1500,"Metaウェビナー")) | G36: =IFERROR(E36/D36,"") | H36: =IFERROR(C36/E36,"") | I36: =IFERROR(C36/D36*1000,"") | J36: =IFERROR(F36/E36,"") | K36: =IFERROR(C36/F36,"") | L36: =IF(COUNTIFS(日次入力!$A$4:$A$1500,">="&DATE(2026,11,3),日次入力!$A$4:$A$1500,"<="&DATE(2026,11,9),日次入力!$C$4:$C$1500,"Metaウェビナー")=0,"",SUMIFS(日次入力!$H$4:$H$1500,日次入力!$A$4:$A$1500,">="&DATE(2026,11,3),日次入力!$A$4:$A$1500,"<="&DATE(2026,11,9),日次入力!$C$4:$C$1500,"Metaウェビナー")) | M36: =IF(L36="","",IFERROR(L36/F36,"")) | N36: =IF(COUNTIFS(日次入力!$A$4:$A$1500,">="&DATE(2026,11,3),日次入力!$A$4:$A$1500,"<="&DATE(2026,11,9),日次入力!$C$4:$C$1500,"Metaウェビナー")=0,"",SUMIFS(日次入力!$I$4:$I$1500,日次入力!$A$4:$A$1500,">="&DATE(2026,11,3),日次入力!$A$4:$A$1500,"<="&DATE(2026,11,9),日次入力!$C$4:$C$1500,"Metaウェビナー")) | O36: =IF(N36="","",IFERROR(N36/L36,"")) | P36: =IF(N36=0,"",IFERROR(C36/N36,"")) | Q36: =IF(N36=0,"",IFERROR(IF(C36/N36<=用語集!$B$22,"◎ 許容内","✗ 超過"),"—")) -> — | R36: =IFERROR(用語集!$B$22/P36,"")
A37: W32 | B37: 11/10–11/16 | C37: =IF(COUNTIFS(日次入力!$A$4:$A$1500,">="&DATE(2026,11,10),日次入力!$A$4:$A$1500,"<="&DATE(2026,11,16),日次入力!$C$4:$C$1500,"Metaウェビナー")=0,"",SUMIFS(日次入力!$D$4:$D$1500,日次入力!$A$4:$A$1500,">="&DATE(2026,11,10),日次入力!$A$4:$A$1500,"<="&DATE(2026,11,16),日次入力!$C$4:$C$1500,"Metaウェビナー")) | D37: =IF(COUNTIFS(日次入力!$A$4:$A$1500,">="&DATE(2026,11,10),日次入力!$A$4:$A$1500,"<="&DATE(2026,11,16),日次入力!$C$4:$C$1500,"Metaウェビナー")=0,"",SUMIFS(日次入力!$E$4:$E$1500,日次入力!$A$4:$A$1500,">="&DATE(2026,11,10),日次入力!$A$4:$A$1500,"<="&DATE(2026,11,16),日次入力!$C$4:$C$1500,"Metaウェビナー")) | E37: =IF(COUNTIFS(日次入力!$A$4:$A$1500,">="&DATE(2026,11,10),日次入力!$A$4:$A$1500,"<="&DATE(2026,11,16),日次入力!$C$4:$C$1500,"Metaウェビナー")=0,"",SUMIFS(日次入力!$F$4:$F$1500,日次入力!$A$4:$A$1500,">="&DATE(2026,11,10),日次入力!$A$4:$A$1500,"<="&DATE(2026,11,16),日次入力!$C$4:$C$1500,"Metaウェビナー")) | F37: =IF(COUNTIFS(日次入力!$A$4:$A$1500,">="&DATE(2026,11,10),日次入力!$A$4:$A$1500,"<="&DATE(2026,11,16),日次入力!$C$4:$C$1500,"Metaウェビナー")=0,"",SUMIFS(日次入力!$G$4:$G$1500,日次入力!$A$4:$A$1500,">="&DATE(2026,11,10),日次入力!$A$4:$A$1500,"<="&DATE(2026,11,16),日次入力!$C$4:$C$1500,"Metaウェビナー")) | G37: =IFERROR(E37/D37,"") | H37: =IFERROR(C37/E37,"") | I37: =IFERROR(C37/D37*1000,"") | J37: =IFERROR(F37/E37,"") | K37: =IFERROR(C37/F37,"") | L37: =IF(COUNTIFS(日次入力!$A$4:$A$1500,">="&DATE(2026,11,10),日次入力!$A$4:$A$1500,"<="&DATE(2026,11,16),日次入力!$C$4:$C$1500,"Metaウェビナー")=0,"",SUMIFS(日次入力!$H$4:$H$1500,日次入力!$A$4:$A$1500,">="&DATE(2026,11,10),日次入力!$A$4:$A$1500,"<="&DATE(2026,11,16),日次入力!$C$4:$C$1500,"Metaウェビナー")) | M37: =IF(L37="","",IFERROR(L37/F37,"")) | N37: =IF(COUNTIFS(日次入力!$A$4:$A$1500,">="&DATE(2026,11,10),日次入力!$A$4:$A$1500,"<="&DATE(2026,11,16),日次入力!$C$4:$C$1500,"Metaウェビナー")=0,"",SUMIFS(日次入力!$I$4:$I$1500,日次入力!$A$4:$A$1500,">="&DATE(2026,11,10),日次入力!$A$4:$A$1500,"<="&DATE(2026,11,16),日次入力!$C$4:$C$1500,"Metaウェビナー")) | O37: =IF(N37="","",IFERROR(N37/L37,"")) | P37: =IF(N37=0,"",IFERROR(C37/N37,"")) | Q37: =IF(N37=0,"",IFERROR(IF(C37/N37<=用語集!$B$22,"◎ 許容内","✗ 超過"),"—")) -> — | R37: =IFERROR(用語集!$B$22/P37,"")
A38: W33 | B38: 11/17–11/23 | C38: =IF(COUNTIFS(日次入力!$A$4:$A$1500,">="&DATE(2026,11,17),日次入力!$A$4:$A$1500,"<="&DATE(2026,11,23),日次入力!$C$4:$C$1500,"Metaウェビナー")=0,"",SUMIFS(日次入力!$D$4:$D$1500,日次入力!$A$4:$A$1500,">="&DATE(2026,11,17),日次入力!$A$4:$A$1500,"<="&DATE(2026,11,23),日次入力!$C$4:$C$1500,"Metaウェビナー")) | D38: =IF(COUNTIFS(日次入力!$A$4:$A$1500,">="&DATE(2026,11,17),日次入力!$A$4:$A$1500,"<="&DATE(2026,11,23),日次入力!$C$4:$C$1500,"Metaウェビナー")=0,"",SUMIFS(日次入力!$E$4:$E$1500,日次入力!$A$4:$A$1500,">="&DATE(2026,11,17),日次入力!$A$4:$A$1500,"<="&DATE(2026,11,23),日次入力!$C$4:$C$1500,"Metaウェビナー")) | E38: =IF(COUNTIFS(日次入力!$A$4:$A$1500,">="&DATE(2026,11,17),日次入力!$A$4:$A$1500,"<="&DATE(2026,11,23),日次入力!$C$4:$C$1500,"Metaウェビナー")=0,"",SUMIFS(日次入力!$F$4:$F$1500,日次入力!$A$4:$A$1500,">="&DATE(2026,11,17),日次入力!$A$4:$A$1500,"<="&DATE(2026,11,23),日次入力!$C$4:$C$1500,"Metaウェビナー")) | F38: =IF(COUNTIFS(日次入力!$A$4:$A$1500,">="&DATE(2026,11,17),日次入力!$A$4:$A$1500,"<="&DATE(2026,11,23),日次入力!$C$4:$C$1500,"Metaウェビナー")=0,"",SUMIFS(日次入力!$G$4:$G$1500,日次入力!$A$4:$A$1500,">="&DATE(2026,11,17),日次入力!$A$4:$A$1500,"<="&DATE(2026,11,23),日次入力!$C$4:$C$1500,"Metaウェビナー")) | G38: =IFERROR(E38/D38,"") | H38: =IFERROR(C38/E38,"") | I38: =IFERROR(C38/D38*1000,"") | J38: =IFERROR(F38/E38,"") | K38: =IFERROR(C38/F38,"") | L38: =IF(COUNTIFS(日次入力!$A$4:$A$1500,">="&DATE(2026,11,17),日次入力!$A$4:$A$1500,"<="&DATE(2026,11,23),日次入力!$C$4:$C$1500,"Metaウェビナー")=0,"",SUMIFS(日次入力!$H$4:$H$1500,日次入力!$A$4:$A$1500,">="&DATE(2026,11,17),日次入力!$A$4:$A$1500,"<="&DATE(2026,11,23),日次入力!$C$4:$C$1500,"Metaウェビナー")) | M38: =IF(L38="","",IFERROR(L38/F38,"")) | N38: =IF(COUNTIFS(日次入力!$A$4:$A$1500,">="&DATE(2026,11,17),日次入力!$A$4:$A$1500,"<="&DATE(2026,11,23),日次入力!$C$4:$C$1500,"Metaウェビナー")=0,"",SUMIFS(日次入力!$I$4:$I$1500,日次入力!$A$4:$A$1500,">="&DATE(2026,11,17),日次入力!$A$4:$A$1500,"<="&DATE(2026,11,23),日次入力!$C$4:$C$1500,"Metaウェビナー")) | O38: =IF(N38="","",IFERROR(N38/L38,"")) | P38: =IF(N38=0,"",IFERROR(C38/N38,"")) | Q38: =IF(N38=0,"",IFERROR(IF(C38/N38<=用語集!$B$22,"◎ 許容内","✗ 超過"),"—")) -> — | R38: =IFERROR(用語集!$B$22/P38,"")
A39: W34 | B39: 11/24–11/30 | C39: =IF(COUNTIFS(日次入力!$A$4:$A$1500,">="&DATE(2026,11,24),日次入力!$A$4:$A$1500,"<="&DATE(2026,11,30),日次入力!$C$4:$C$1500,"Metaウェビナー")=0,"",SUMIFS(日次入力!$D$4:$D$1500,日次入力!$A$4:$A$1500,">="&DATE(2026,11,24),日次入力!$A$4:$A$1500,"<="&DATE(2026,11,30),日次入力!$C$4:$C$1500,"Metaウェビナー")) | D39: =IF(COUNTIFS(日次入力!$A$4:$A$1500,">="&DATE(2026,11,24),日次入力!$A$4:$A$1500,"<="&DATE(2026,11,30),日次入力!$C$4:$C$1500,"Metaウェビナー")=0,"",SUMIFS(日次入力!$E$4:$E$1500,日次入力!$A$4:$A$1500,">="&DATE(2026,11,24),日次入力!$A$4:$A$1500,"<="&DATE(2026,11,30),日次入力!$C$4:$C$1500,"Metaウェビナー")) | E39: =IF(COUNTIFS(日次入力!$A$4:$A$1500,">="&DATE(2026,11,24),日次入力!$A$4:$A$1500,"<="&DATE(2026,11,30),日次入力!$C$4:$C$1500,"Metaウェビナー")=0,"",SUMIFS(日次入力!$F$4:$F$1500,日次入力!$A$4:$A$1500,">="&DATE(2026,11,24),日次入力!$A$4:$A$1500,"<="&DATE(2026,11,30),日次入力!$C$4:$C$1500,"Metaウェビナー")) | F39: =IF(COUNTIFS(日次入力!$A$4:$A$1500,">="&DATE(2026,11,24),日次入力!$A$4:$A$1500,"<="&DATE(2026,11,30),日次入力!$C$4:$C$1500,"Metaウェビナー")=0,"",SUMIFS(日次入力!$G$4:$G$1500,日次入力!$A$4:$A$1500,">="&DATE(2026,11,24),日次入力!$A$4:$A$1500,"<="&DATE(2026,11,30),日次入力!$C$4:$C$1500,"Metaウェビナー")) | G39: =IFERROR(E39/D39,"") | H39: =IFERROR(C39/E39,"") | I39: =IFERROR(C39/D39*1000,"") | J39: =IFERROR(F39/E39,"") | K39: =IFERROR(C39/F39,"") | L39: =IF(COUNTIFS(日次入力!$A$4:$A$1500,">="&DATE(2026,11,24),日次入力!$A$4:$A$1500,"<="&DATE(2026,11,30),日次入力!$C$4:$C$1500,"Metaウェビナー")=0,"",SUMIFS(日次入力!$H$4:$H$1500,日次入力!$A$4:$A$1500,">="&DATE(2026,11,24),日次入力!$A$4:$A$1500,"<="&DATE(2026,11,30),日次入力!$C$4:$C$1500,"Metaウェビナー")) | M39: =IF(L39="","",IFERROR(L39/F39,"")) | N39: =IF(COUNTIFS(日次入力!$A$4:$A$1500,">="&DATE(2026,11,24),日次入力!$A$4:$A$1500,"<="&DATE(2026,11,30),日次入力!$C$4:$C$1500,"Metaウェビナー")=0,"",SUMIFS(日次入力!$I$4:$I$1500,日次入力!$A$4:$A$1500,">="&DATE(2026,11,24),日次入力!$A$4:$A$1500,"<="&DATE(2026,11,30),日次入力!$C$4:$C$1500,"Metaウェビナー")) | O39: =IF(N39="","",IFERROR(N39/L39,"")) | P39: =IF(N39=0,"",IFERROR(C39/N39,"")) | Q39: =IF(N39=0,"",IFERROR(IF(C39/N39<=用語集!$B$22,"◎ 許容内","✗ 超過"),"—")) -> — | R39: =IFERROR(用語集!$B$22/P39,"")
